Workbook

Sheet Policies
A1: Policy Name | B1: Current Path | C1: Proposed Path | D1: Review Status | E1: Has policy.yml | F1: Notes
A2: Verra VM0007 REDD+ Methodology Framework | B2: Verra/Verified Carbon Standard (VCS)/VM0007 REDD+ Methodology Framework | C2: (edit if path should change) | D2: not-started
A3: VM0044 | B3: Verra/VM0044 | C3: Verra/VM0044 | D3: merged | E3: YES
A4: African Clean Enery (ACE) | B4: African Clean Enery (ACE) | C4: African Clean Enery (ACE) | D4: not-started
A5: CDM ACM0001 | B5: Clean Development Mechanism (CDM)/CDM ACM0001 | C5: Clean Development Mechanism (CDM)/CDM ACM0001 | D5: not-started
A6: CDM ACM0002 | B6: Clean Development Mechanism (CDM)/CDM ACM0002 | C6: Clean Development Mechanism (CDM)/CDM ACM0002 | D6: not-started
A7: CDM ACM0007 | B7: Clean Development Mechanism (CDM)/CDM ACM0007 | C7: Clean Development Mechanism (CDM)/CDM ACM0007 | D7: not-started
A8: CDM ACM0018 | B8: Clean Development Mechanism (CDM)/CDM ACM0018 | C8: Clean Development Mechanism (CDM)/CDM ACM0018 | D8: not-started
A9: CDM AMS-I.A | B9: Clean Development Mechanism (CDM)/CDM AMS-I.A | C9: Clean Development Mechanism (CDM)/CDM AMS-I.A | D9: not-started
A10: CDM AMS-I.C | B10: Clean Development Mechanism (CDM)/CDM AMS-I.C | C10: Clean Development Mechanism (CDM)/CDM AMS-I.C | D10: not-started
A11: CDM AMS-I.D | B11: Clean Development Mechanism (CDM)/CDM AMS-I.D | C11: Clean Development Mechanism (CDM)/CDM AMS-I.D | D11: not-started
A12: CDM AMS-I.E | B12: Clean Development Mechanism (CDM)/CDM AMS-I.E | C12: Clean Development Mechanism (CDM)/CDM AMS-I.E | D12: not-started
A13: CDM AMS-I.F | B13: Clean Development Mechanism (CDM)/CDM AMS-I.F | C13: Clean Development Mechanism (CDM)/CDM AMS-I.F | D13: not-started
A14: CDM AMS-II.G | B14: Clean Development Mechanism (CDM)/CDM AMS-II.G | C14: Clean Development Mechanism (CDM)/CDM AMS-II.G | D14: not-started
A15: CDM AMS-II.J | B15: Clean Development Mechanism (CDM)/CDM AMS-II.J | C15: Clean Development Mechanism (CDM)/CDM AMS-II.J | D15: not-started
... A103: Deloitte ESI Mangrove | B103: Work In Progress/Deloitte ESI Mangrove | C103: Work In Progress/Deloitte ESI Mangrove | D103: not-started

Sheet Required Fields
A1: Policy Name | B1: Review Status | C1: id * | D1: name * | E1: version * | F1: description * | G1: policy_type * | H1: status * | I1: license * | J1: category * | K1: authors * | L1: tags
A2: ← auto-filled from Policies | B2: ← auto-filled from Policies | C2: verra-vm0007-redd-plus | D2: Verra VM0007 REDD+ Methodology Framework | E2: 1.0.0 | F2: Implements Verra VM0007 REDD+ Methodology Framework v7.0, issuing VCU tokens on Hedera. | G2: standard-implementation | H2: active | I2: Apache-2.0 | J2: carbon-credits | K2: Hedera | Hashgraph Association | L2: verra, vm0007, land-use, redd-plus
A3: ==Policies!A3 -> VM0044 | B3: ==Policies!D3 -> merged | C3: verra-vm0044 | D3: VM0044 | E3: 1.0.0 | G3: standard-implementation | H3: draft | I3: Apache-2.0 | J3: carbon-credits | L3: verra, vm0044, land-use
A4: ==Policies!A4 -> African Clean Enery (ACE) | B4: ==Policies!D4 -> not-started | C4: ace-african-clean-enery-ace | D4: African Clean Enery (ACE) | E4: 1.0.0 | G4: standard-implementation | H4: draft | I4: Apache-2.0 | J4: carbon-credits | L4: african-clean-energy
A5: ==Policies!A5 -> CDM ACM0001 | B5: ==Policies!D5 -> not-started | C5: cdm-cdm-acm0001 | D5: CDM ACM0001 | E5: 1.0.0 | G5: standard-implementation | H5: draft | I5: Apache-2.0 | J5: carbon-credits | L5: cdm
A6: ==Policies!A6 -> CDM ACM0002 | B6: ==Policies!D6 -> not-started | C6: cdm-cdm-acm0002 | D6: CDM ACM0002 | E6: 1.0.0 | G6: standard-implementation | H6: draft | I6: Apache-2.0 | J6: carbon-credits | L6: cdm
A7: ==Policies!A7 -> CDM ACM0007 | B7: ==Policies!D7 -> not-started | C7: cdm-cdm-acm0007 | D7: CDM ACM0007 | E7: 1.0.0 | G7: standard-implementation | H7: draft | I7: Apache-2.0 | J7: carbon-credits | L7: cdm
A8: ==Policies!A8 -> CDM ACM0018 | B8: ==Policies!D8 -> not-started | C8: cdm-cdm-acm0018 | D8: CDM ACM0018 | E8: 1.0.0 | G8: standard-implementation | H8: draft | I8: Apache-2.0 | J8: carbon-credits | L8: cdm
A9: ==Policies!A9 -> CDM AMS-I.A | B9: ==Policies!D9 -> not-started | C9: cdm-cdm-ams-i-a | D9: CDM AMS-I.A | E9: 1.0.0 | G9: standard-implementation | H9: draft | I9: Apache-2.0 | J9: carbon-credits | L9: cdm
A10: ==Policies!A10 -> CDM AMS-I.C | B10: ==Policies!D10 -> not-started | C10: cdm-cdm-ams-i-c | D10: CDM AMS-I.C | E10: 1.0.0 | G10: standard-implementation | H10: draft | I10: Apache-2.0 | J10: carbon-credits | L10: cdm
A11: ==Policies!A11 -> CDM AMS-I.D | B11: ==Policies!D11 -> not-started | C11: cdm-cdm-ams-i-d | D11: CDM AMS-I.D | E11: 1.0.0 | G11: standard-implementation | H11: draft | I11: Apache-2.0 | J11: carbon-credits | L11: cdm
A12: ==Policies!A12 -> CDM AMS-I.E | B12: ==Policies!D12 -> not-started | C12: cdm-cdm-ams-i-e | D12: CDM AMS-I.E | E12: 1.0.0 | G12: standard-implementation | H12: draft | I12: Apache-2.0 | J12: carbon-credits | L12: cdm
A13: ==Policies!A13 -> CDM AMS-I.F | B13: ==Policies!D13 -> not-started | C13: cdm-cdm-ams-i-f | D13: CDM AMS-I.F | E13: 1.0.0 | G13: standard-implementation | H13: draft | I13: Apache-2.0 | J13: carbon-credits | L13: cdm
A14: ==Policies!A14 -> CDM AMS-II.G | B14: ==Policies!D14 -> not-started | C14: cdm-cdm-ams-ii-g | D14: CDM AMS-II.G | E14: 1.0.0 | G14: standard-implementation | H14: draft | I14: Apache-2.0 | J14: carbon-credits | L14: cdm
... A35: ==Policies!A35 -> Soil Carbon Coalition MRV | B35: ==Policies!D35 -> not-started | C35: dovu-soil-carbon-coalition-mrv | D35: Soil Carbon Coalition MRV | E35: 1.0.0 | G35: mrv-template | H35: draft | I35: Apache-2.0 | J35: sustainable-agriculture | L35: dovu, agriculture
A36: ==Policies!A36 -> EUDR Precheck | B36: ==Policies!D36 -> not-started | C36: eudr-eudr-precheck | D36: EUDR Precheck | E36: 1.0.0 | G36: novel-methodology | H36: draft | I36: Apache-2.0 | J36: supply-chain
A37: ==Policies!A37 -> GCC - Amana | B37: ==Policies!D37 -> not-started | C37: gcc-gcc-amana | D37: GCC - Amana | E37: 1.0.0 | G37: standard-implementation | H37: draft | I37: Apache-2.0 | J37: carbon-credits | L37: gcc
A38: ==Policies!A38 -> GCCM001 | B38: ==Policies!D38 -> not-started | C38: gcc-gccm001 | D38: GCCM001 | E38: 1.0.0 | G38: standard-implementation | H38: draft | I38: Apache-2.0 | J38: carbon-credits | L38: gcc, gccm001
A39: ==Policies!A39 -> Gold Standard Carbon Sequestration | B39: ==Policies!D39 -> not-started | C39: gs-gold-standard-carbon-sequestration | D39: Gold Standard Carbon Sequestration | E39: 1.0.0 | G39: standard-implementation | H39: draft | I39: Apache-2.0 | J39: carbon-credits | L39: gold-standard
A40: ==Policies!A40 -> Gold Standard Methodology – Emission Reductions from Safe Drinking Water | B40: ==Policies!D40 -> not-started | C40: gs-gold-standard-methodology-emission-reductions-from-safe-drinking-water | D40: Gold Standard Methodology – Emission Reductions from Safe Drinking Water | E40: 1.0.0 | G40: standard-implementation | H40: draft | I40: Apache-2.0 | J40: carbon-credits | L40: gold-standard
A41: ==Policies!A41 -> GS-TPDDTEC(v3.1.0) | B41: ==Policies!D41 -> not-started | C41: gs-gs-tpddtecv3-1-0 | D41: GS-TPDDTEC(v3.1.0) | E41: 1.0.0 | G41: standard-implementation | H41: draft | I41: Apache-2.0 | J41: carbon-credits | L41: gold-standard
A42: ==Policies!A42 -> GoldStandard AR | B42: ==Policies!D42 -> not-started | C42: gs-goldstandard-ar | D42: GoldStandard AR | E42: 1.0.0 | G42: standard-implementation | H42: draft | I42: Apache-2.0 | J42: carbon-credits | L42: gold-standard
A43: ==Policies!A43 -> MECD v1.2 | B43: ==Policies!D43 -> not-started | C43: gs-mecd-v1-2 | D43: MECD v1.2 | E43: 1.0.0 | G43: standard-implementation | H43: draft | I43: Apache-2.0 | J43: carbon-credits | L43: gold-standard, mecd-v1-2
A44: ==Policies!A44 -> MECD v2.0 | B44: ==Policies!D44 -> not-started | C44: gs-mecd-v2-0 | D44: MECD v2.0 | E44: 1.0.0 | G44: standard-implementation | H44: draft | I44: Apache-2.0 | J44: carbon-credits | L44: gold-standard, mecd-v2-0
A45: ==Policies!A45 -> Methane Emission Reduction by Adjusted Water Management Practice in Rice Cultivation | B45: ==Policies!D45 -> not-started | C45: gs-methane-emission-reduction-by-adjusted-water-management-practice-in-rice-cultivation | D45: Methane Emission Reduction by Adjusted Water Management Practice in Rice Cultivation | E45: 1.0.0 | G45: standard-implementation | H45: draft | I45: Apache-2.0 | J45: carbon-credits | L45: gold-standard
A46: ==Policies!A46 -> TPDDTEC v4.0 | B46: ==Policies!D46 -> not-started | C46: gs-tpddtec-v4-0 | D46: TPDDTEC v4.0 | E46: 1.0.0 | G46: standard-implementation | H46: draft | I46: Apache-2.0 | J46: carbon-credits | L46: gold-standard
A47: ==Policies!A47 -> GHG Protocol Corporate Standard v2 | B47: ==Policies!D47 -> not-started | C47: ghg-ghg-protocol-corporate-standard-v2 | D47: GHG Protocol Corporate Standard v2 | E47: 1.0.0 | G47: standard-implementation | H47: draft | I47: Apache-2.0 | J47: emission-reporting | L47: ghg-protocol, industrial
A48: ==Policies!A48 -> GHG Protocol Corporate Standard v3 | B48: ==Policies!D48 -> not-started | C48: ghg-ghg-protocol-corporate-standard-v3 | D48: GHG Protocol Corporate Standard v3 | E48: 1.0.0 | G48: standard-implementation | H48: draft | I48: Apache-2.0 | J48: emission-reporting | L48: ghg-protocol, industrial
... A57: ==Policies!A57 -> Remote Work Policy (Scope 3) | B57: ==Policies!D57 -> not-started | C57: ghg-remote-work-policy-scope-3 | D57: Remote Work Policy (Scope 3) | E57: 1.0.0 | G57: standard-implementation | H57: draft | I57: Apache-2.0 | J57: emission-reporting | L57: ghg-protocol, industrial
A58: ==Policies!A58 -> Agrify Regenerative Agriculture Methodology | B58: ==Policies!D58 -> not-started | C58: hackathon-agrify-regenerative-agriculture-methodology | D58: Agrify Regenerative Agriculture Methodology | E58: 1.0.0 | G58: proof-of-concept | H58: draft | I58: Apache-2.0
A59: ==Policies!A59 -> AM0124 -Hydrogen Production from Electrolysis of water | B59: ==Policies!D59 -> not-started | C59: hackathon-am0124-hydrogen-production-from-electrolysis-of-water | D59: AM0124 -Hydrogen Production from Electrolysis of water | E59: 1.0.0 | G59: proof-of-concept | H59: draft | I59: Apache-2.0 | L59: am0124
A60: ==Policies!A60 -> AMS-3.C - Emission reduction by electric and hybrid vehicles | B60: ==Policies!D60 -> not-started | C60: hackathon-ams-3-c-emission-reduction-by-electric-and-hybrid-vehicles | D60: AMS-3.C - Emission reduction by electric and hybrid vehicles | E60: 1.0.0 | G60: proof-of-concept | H60: draft | I60: Apache-2.0
A61: ==Policies!A61 -> AMS-3.Z | B61: ==Policies!D61 -> not-started | C61: hackathon-ams-3-z | D61: AMS-3.Z | E61: 1.0.0 | G61: proof-of-concept | H61: draft | I61: Apache-2.0
A62: ==Policies!A62 -> Carbon Forward Issuance Based on the Verra VM0047 Methodology | B62: ==Policies!D62 -> not-started | C62: hackathon-carbon-forward-issuance-based-on-the-verra-vm0047-methodology | D62: Carbon Forward Issuance Based on the Verra VM0047 Methodology | E62: 1.0.0 | G62: proof-of-concept | H62: draft | I62: Apache-2.0
A63: ==Policies!A63 -> CDM ACM0014 | B63: ==Policies!D63 -> not-started | C63: hackathon-cdm-acm0014 | D63: CDM ACM0014 | E63: 1.0.0 | G63: proof-of-concept | H63: draft | I63: Apache-2.0
A64: ==Policies!A64 -> Chain Assurance | B64: ==Policies!D64 -> not-started | C64: hackathon-chain-assurance | D64: Chain Assurance | E64: 1.0.0 | G64: proof-of-concept | H64: draft | I64: Apache-2.0
A65: ==Policies!A65 -> EcoRegenAlliance-main | B65: ==Policies!D65 -> not-started | C65: hackathon-ecoregenalliance-main | D65: EcoRegenAlliance-main | E65: 1.0.0 | G65: proof-of-concept | H65: draft | I65: Apache-2.0
A66: ==Policies!A66 -> ESG verifier | B66: ==Policies!D66 -> not-started | C66: hackathon-esg-verifier | D66: ESG verifier | E66: 1.0.0 | G66: proof-of-concept | H66: draft | I66: Apache-2.0
A67: ==Policies!A67 -> Food-Loss-Waste-International-Policy | B67: ==Policies!D67 -> not-started | C67: hackathon-food-loss-waste-international-policy | D67: Food-Loss-Waste-International-Policy | E67: 1.0.0 | G67: proof-of-concept | H67: draft | I67: Apache-2.0
A68: ==Policies!A68 -> GF0001 | B68: ==Policies!D68 -> not-started | C68: hackathon-gf0001 | D68: GF0001 | E68: 1.0.0 | G68: proof-of-concept | H68: draft | I68: Apache-2.0
...

Sheet Optional Fields
A1: Policy Name | B1: Review Status | C1: standard_body | D1: methodology_id | E1: methodology_version | F1: token_type | G1: token_standard | H1: registry_status | I1: registry_body | J1: registry_reference | K1: registry_accepted_date | L1: hedera_timestamp | M1: sdg_alignment | N1: sector | O1: roles | P1: guardian_version_min | Q1: category_note | R1: policy_type_note | S1: homepage | T1: support | U1: thumbnail | V1: supersedes | W1: superseded_by
A2: ← auto-filled from Policies | B2: ← auto-filled from Policies | C2: Verra | D2: VM0007 | E2: 7.0 | F2: VCU | G2: fungible | H2: validated | I2: Verra | L2: 1707207286.119377003 | M2: 13, 15 | N2: land-use | O2: Admin, Project Proponent, VVB | P2: 2.20.0 | S2: https://verra.org/methodologies/vm0007-redd-methodology-framework-redd-mf/ | T2: https://github.com/hashgraph/guardian/issues | U2: assets/thumbnail.png
A3: ==Policies!A3 -> VM0044 | B3: ==Policies!D3 -> merged | C3: Verra | D3: VM0044 | F3: VCU | G3: fungible | H3: none | N3: land-use | O3: Admin, Project Proponent, VVB
A4: ==Policies!A4 -> African Clean Enery (ACE) | B4: ==Policies!D4 -> not-started | C4: African Clean Energy | H4: none
A5: ==Policies!A5 -> CDM ACM0001 | B5: ==Policies!D5 -> not-started | C5: CDM | F5: CER | G5: fungible | H5: none | O5: Admin, Project Proponent, VVB
A6: ==Policies!A6 -> CDM ACM0002 | B6: ==Policies!D6 -> not-started | C6: CDM | F6: CER | G6: fungible | H6: none | O6: Admin, Project Proponent, VVB
A7: ==Policies!A7 -> CDM ACM0007 | B7: ==Policies!D7 -> not-started | C7: CDM | F7: CER | G7: fungible | H7: none | O7: Admin, Project Proponent, VVB
A8: ==Policies!A8 -> CDM ACM0018 | B8: ==Policies!D8 -> not-started | C8: CDM | F8: CER | G8: fungible | H8: none | O8: Admin, Project Proponent, VVB
A9: ==Policies!A9 -> CDM AMS-I.A | B9: ==Policies!D9 -> not-started | C9: CDM | F9: CER | G9: fungible | H9: none | O9: Admin, Project Proponent, VVB
A10: ==Policies!A10 -> CDM AMS-I.C | B10: ==Policies!D10 -> not-started | C10: CDM | F10: CER | G10: fungible | H10: none | O10: Admin, Project Proponent, VVB
A11: ==Policies!A11 -> CDM AMS-I.D | B11: ==Policies!D11 -> not-started | C11: CDM | F11: CER | G11: fungible | H11: none | O11: Admin, Project Proponent, VVB
A12: ==Policies!A12 -> CDM AMS-I.E | B12: ==Policies!D12 -> not-started | C12: CDM | F12: CER | G12: fungible | H12: none | O12: Admin, Project Proponent, VVB
A13: ==Policies!A13 -> CDM AMS-I.F | B13: ==Policies!D13 -> not-started | C13: CDM | F13: CER | G13: fungible | H13: none | O13: Admin, Project Proponent, VVB
A14: ==Policies!A14 -> CDM AMS-II.G | B14: ==Policies!D14 -> not-started | C14: CDM | F14: CER | G14: fungible | H14: none | O14: Admin, Project Proponent, VVB
A15: ==Policies!A15 -> CDM AMS-II.J | B15: ==Policies!D15 -> not-started | C15: CDM | F15: CER | G15: fungible | H15: none | O15: Admin, Project Proponent, VVB
A16: ==Policies!A16 -> CDM AMS-III.AR | B16: ==Policies!D16 -> not-started | C16: CDM | F16: CER | G16: fungible | H16: none | O16: Admin, Project Proponent, VVB
... A22: ==Policies!A22 -> CDM AR-ACM0003 | B22: ==Policies!D22 -> not-started | C22: CDM | F22: CER | G22: fungible | H22: none | O22: Admin, Project Proponent, VVB
A23: ==Policies!A23 -> US Landfill | B23: ==Policies!D23 -> not-started | C23: CAR | H23: none | O23: Admin, Project Proponent, VVB
A24: ==Policies!A24 -> VM0047 V1.1 | B24: ==Policies!D24 -> not-started | C24: DLT Earth | D24: VM0047 | H24: none | N24: land-use
A25: ==Policies!A25 -> MMCM | B25: ==Policies!D25 -> not-started | C25: Dovu | H25: none | N25: agriculture
A26: ==Policies!A26 -> Agrecalc MRV | B26: ==Policies!D26 -> not-started | C26: Dovu | H26: none | N26: agriculture
A27: ==Policies!A27 -> Agricultural soils of Western Australia MRV | B27: ==Policies!D27 -> not-started | C27: Dovu | H27: none | N27: agriculture
A28: ==Policies!A28 -> Carbon Space MRV | B28: ==Policies!D28 -> not-started | C28: Dovu | H28: none | N28: agriculture
A29: ==Policies!A29 -> Cool Farm Tool MRV | B29: ==Policies!D29 -> not-started | C29: Dovu | H29: none | N29: agriculture
A30: ==Policies!A30 -> Geotree MRV | B30: ==Policies!D30 -> not-started | C30: Dovu | H30: none | N30: agriculture
A31: ==Policies!A31 -> GHG Assessment Guideline Soil MRV | B31: ==Policies!D31 -> not-started | C31: Dovu | H31: none | N31: agriculture
A32: ==Policies!A32 -> Grain Data Solution MRV | B32: ==Policies!D32 -> not-started | C32: Dovu | H32: none | N32: agriculture
A33: ==Policies!A33 -> Microbial-Mineral Carbon Stabilization (MIMICS) MRV | B33: ==Policies!D33 -> not-started | C33: Dovu | H33: none | N33: agriculture
A34: ==Policies!A34 -> RothC MRV | B34: ==Policies!D34 -> not-started | C34: Dovu | H34: none | N34: agriculture
A35: ==Policies!A35 -> Soil Carbon Coalition MRV | B35: ==Policies!D35 -> not-started | C35: Dovu | H35: none | N35: agriculture
A36: ==Policies!A36 -> EUDR Precheck | B36: ==Policies!D36 -> not-started
A37: ==Policies!A37 -> GCC - Amana | B37: ==Policies!D37 -> not-started | C37: GCC | H37: none | O37: Admin, Project Proponent, VVB
A38: ==Policies!A38 -> GCCM001 | B38: ==Policies!D38 -> not-started | C38: GCC | D38: GCCM001 | H38: none | O38: Admin, Project Proponent, VVB
A39: ==Policies!A39 -> Gold Standard Carbon Sequestration | B39: ==Policies!D39 -> not-started | C39: Gold Standard | H39: none | O39: Admin, Project Proponent, VVB
A40: ==Policies!A40 -> Gold Standard Methodology – Emission Reductions from Safe Drinking Water | B40: ==Policies!D40 -> not-started | C40: Gold Standard | H40: none | O40: Admin, Project Proponent, VVB
A41: ==Policies!A41 -> GS-TPDDTEC(v3.1.0) | B41: ==Policies!D41 -> not-started | C41: Gold Standard | H41: none | O41: Admin, Project Proponent, VVB
A42: ==Policies!A42 -> GoldStandard AR | B42: ==Policies!D42 -> not-started | C42: Gold Standard | H42: none | O42: Admin, Project Proponent, VVB
A43: ==Policies!A43 -> MECD v1.2 | B43: ==Policies!D43 -> not-started | C43: Gold Standard | D43: MECD v1.2 | H43: none | O43: Admin, Project Proponent, VVB
A44: ==Policies!A44 -> MECD v2.0 | B44: ==Policies!D44 -> not-started | C44: Gold Standard | D44: MECD v2.0 | H44: none | O44: Admin, Project Proponent, VVB
A45: ==Policies!A45 -> Methane Emission Reduction by Adjusted Water Management Practice in Rice Cultivation | B45: ==Policies!D45 -> not-started | C45: Gold Standard | H45: none | O45: Admin, Project Proponent, VVB
...

Sheet Dropdown Data
A1: review_status | B1: policy_type | C1: status (manifest) | D1: category | E1: token_standard | F1: registry_status | G1: sector | H1: roles (known)
A2: not-started | B2: standard-implementation | C2: draft | D2: carbon-credits | E2: fungible | F2: none | G2: energy | H2: Admin
A3: in-progress | B3: novel-methodology | C3: candidate | D3: emission-reporting | E3: HIP-412-NFT | F3: pending | G3: transport | H3: Project Proponent
A4: ready | B4: mrv-template | C4: active | D4: renewable-energy | E4: none | F4: validated | G4: waste | H4: VVB
A5: merged | B5: proof-of-concept | C5: deprecated | D5: supply-chain | F5: revoked | G5: land-use
B6: toolkit | C6: superseded | D6: sustainable-agriculture | G6: industrial
B7: other | D7: water | G7: agriculture
D8: biodiversity | G8: water
D9: waste | G9: other
D10: other

Sheet Manifest Files
A1: Reserved for generated manifest content — leave blank
