Workbook

Sheet Parameters
A1: SR | B1: Description | C1: Parameter | D1: Unit | E1: Reference | F1: Digitalization Status | G1: Option (High Tech/Low Tech) | H1: Required at Validation | I1: Required at Monitoring
A2: 1 | B2: GHG emissions removals at production stage in year y (tCO2e) | C2: ERPS,y | D2: tCO2e | E2: Equation 1 | F2: Output - See appendix | G2: Option 1 and Option 2
A3: 2 | B3: Organic carbon content on a dry weight basis for biochar type t used for application type k in year y (tonnes) | C3: CCt,k,y | D3: tonnes | E3: Equation 1 | F3: Output - See appendix | G3: Option 1 and Option 2
A4: 4 | B4: Coefficient to convert organic carbon to tCO2e | C4: =44/12 -> 3.6666667 | D4: value | E4: Equation 1
A5: 38 | B5: Baseline emissions at application stage | C5: BEAS,y | D5: tCO2e | E5: Not in VM0044 | F5: Can be added in Baseline Emissions | G5: Option 1 and Option 2
A6: 36 | B6: Baseline emissions due to the combustion of waste biomass in year y | C6: BEC,y | D6: tCO2e | E6: Not in VM0044 | F6: Can be added in Baseline Emissions | G6: Option 1 and Option 2
B7: Baseline emissions at sourcing stage in year y | C7: BESS,y | D7: tCO2e
A8: 35 | B8: Baseline emissions due to the decomposition of waste biomass in year y | C8: BED,y | D8: tCO2e | E8: Not in VM0044 | F8: Can be added in Baseline Emissions | G8: Option 1 and Option 2
A9: 6 | B9: Organic carbon content of biochar type t produced in production facility p per tonne of biochar, taken on a dry weight basis (percent) | C9: FCp,t,p | D9: Percent | E9: Equation 2 | F9: Unit correction needed: parameter description under equation 2 in VM0044 shows unit as percent, however, this is aded as proportion in calculation engine for accurate calculations. Calculation engine needs update | G9: Option 1 and Option 2 | H9: Yes | I9: Yes
A10: 9 | B10: Emissions associated with the pre-treatment of waste biomass at production facility p in year y (tCO2e) | C10: PED,p,y | D10: tCO2e | E10: Equation 3 | F10: Output - See appendix | G10: Option 1 and Option 2
A11: 17 | B11: Average methane emissions from producing one tonne of biochar in year y (tCH4/tonne). | C11: Fe | E11: Equation 9 | F11: Done | G11: Low Tech Facilities | H11: Yes
A12: 11 | B12: Emissions due to the utilization of auxiliary energy for the purpose of pyrolysis at production facility p in year y (tCO2e) | C12: PEC,p,y | D12: tCO2e | E12: Equation 3 | F12: Output - See appendix | G12: Option 1 and Option 2
A13: 18 | B13: Global warming potential of methane. | C13: GWPCH4 | E13: Equation 9 | F13: Missing: It might already be incorporated in calculation/formulas | G13: Low Tech Facilities | H13: Yes
A14: 41 | B14: Ratio of hydrogen to organic carbon | C14: H:Corg | G14: Option 1 and Option 2 | I14: Yes
A15: 26 | B15: Leakage due to activity shift in year y (tCO2e). Leakage due to activity shift is zero as use of purposely grown biomass for production of biochar is currently not allowed. | C15: LEas,y | D15: tCO2e | E15: Equation 13 | F15: Done | G15: Option 1 and Option 2
A16: 27 | B16: Leakage due to biomass diversion in year y (tCO2e). Leakage due to biomass (waste/residue) diversion is considered negligible since only biomass which would have been combusted or left to decay is utilized for biochar production. | C16: LEbd,y | D16: tCO2e | E16: Equation 13 | F16: Done | G16: Option 1 and Option 2
A17: 29 | B17: Leakage emissions from transportation of biochar from the production facility to the site of end application in year y (tCO2e). | C17: LEtap,y | D17: tCO2e | E17: TOOL12 | F17: Done | G17: Option 1 and Option 2
A18: 28 | B18: Leakage emissions from transportation of waste biomass from sourcing to biochar production facility in year y (tCO2e). As per CDM Tool 16: Project and leakage emissions from biomass, GHG emissions must be accounted for only if transportation distance is more than 200 km. Project proponent must use CDM Tool 12: Project and leakage emissions from transportation of freight to calculate LEts,y | C18: LEts,y | D18: tCO2e | E18: TOOL12 | F18: Done | G18: Option 1 and Option 2
A19: 12 | B19: Total mass of biochar on a dry weight basis produced in production facility p in year y (tonnes) | C19: Mp,y | D19: tonnes | E19: Equation 3 | F19: Done | G19: Option 1 and Option 2 | I19: Yes
A20: 5 | B20: Mass on a dry weight basis of biochar type t for application type k produced at the production facility p in year y (tonnes) | C20: Mt,k,p,y | D20: tonnes | E20: Equation 2 | F20: Done | G20: Option 1 and Option 2 | I20: Yes
A21: 20 | B21: Emissions from processing of biochar type t for application type k in year y (tCO2e) | C21: EP,t,k,y | D21: tCO2e | E21: Equation 11 | F21: Done | G21: Option 1 and Option 2
A22: 21 | B22: Emissions from utilization of biochar type t for application type k in year y (tCO2e) | C22: Eap,t,k,y | D22: tCO2e | E22: Equation 11 | F22: Done | G22: Option 1 and Option 2
A23: 22 | B23: Emissions from processing of biochar for application type k in year y (tCO2e) | C23: EP,k,y | D23: tCO2e | E23: Equation 12 | F23: Output - See appendix | G23: Option 1 and Option 2
A24: 19 | B24: GHG emissions at application stage in year y (tCO2e) | C24: PEAS,y | D24: tCO2e | E24: Equations 11, 15 | F24: ERAS,y in appendix should actually be PEAS,y | G24: Option 1 and Option 2
A25: 15 | B25: Emissions associated with use of grid-connected electricity utilized for starting the reactor at production facility p in year y (tCO2e). | C25: PECE,p,y | D25: tCO2e | E25: TOOL05 | F25: Done | G25: Option 1 and Option 2
A26: 25 | B26: Total leakage emissions in year y (tCO2e) | C26: LEy | D26: tCO2e | E26: Equation 13 | F26: Output - See appendix | G26: Option 1 and Option 2
A27: 16 | B27: Emissions associated with combustion of fossil fuels utilized for starting the reactor at production facility p in year y (tCO2e) | C27: PECF,p,y | D27: tCO2e | E27: TOOL03 | F27: Done | G27: Option 1 and Option 2
A28: 13 | B28: Emissions associated with use of grid-connected electricity utilized for pre_x0002_treatment of waste biomass at production facility p in year y (tCO2e) | C28: PEDE,p,y | D28: tCO2e | E28: TOOL05 | F28: Done | G28: Option 1 and Option 2
A29: 14 | B29: Emissions associated with combustion of fossil fuels utilized for pre-treatment of waste biomass at production facility p in year y (tCO2e). | C29: PEDF,p,y | D29: tCO2e | E29: TOOL03 | F29: Done | G29: Option 1 and Option 2
A30: 10 | B30: Emissions associated with the conversion of waste biomass into biochar at production facility p in year y (tCO2e) | C30: PEP,p,y | D30: tCO2e | E30: Equation 3, 7, and 9 | F30: Missing | G30: Option 1 and Option 2
A31: 30 | B31: GHG emission reductions at sourcing stage in year y (tCO2e) | C31: ERSS,y | D31: tCO2e | E31: Equation 14 | F31: Output - See appendix | G31: Option 1 and Option 2
A32: 31 | B32: Baseline emissions at sourcing stage in year y; conservatively assumed default value of zero (tCO2e) | C32: BESS,y | D32: tCO2e | E32: Equation 14 | F32: Can be added in Baseline Emissions | G32: Option 1 and Option 2
... A36: 8 | B36: Project emissions at the production stage for production of biochar at production facility p in year y (tCO2e) | C36: PEPS,p,y | D36: tCO2e | E36: Equation 3 | F36: Output - See appendix | G36: Option 1 and Option 2
A37: 39 | B37: Project emissions at the production stage for production of biochar type t at production facility p in year y (tCO2e) | C37: PEPS,t,p,y | D37: tCO2e | E37: Equation 1 | G37: Option 1 and Option 2
A38: 32 | B38: Project emissions at sourcing stage in year y, conservatively assumed to be zero (waste biogenic source material is considered as renewable biomass) (tCO2e) | C38: PESS,y | D38: tCO2e | E38: Equation 14 | F38: Missing | G38: Option 1 and Option 2
A39: 7 | B39: Permanence adjustment factor due to decay of biochar per application type k (dimensionless) | C39: PRde,k | D39: value | E39: Equation 2 | F39: Done | G39: Option 1 and Option 2 | H39: Yes
A40: 40 | B40: Average annual production temperature during pyrolysis | C40: Tprod | D40: C | G40: Option 1 and Option 2 | I40: Yes
A41: 42 | B41: Fraction of total waste heat utilized at biochar production facility p | C41: WSp | G41: High Tech Facilities | I41: Yes
B42: the quantity of fuel type i combusted in process j during the year y (mass or volume unit/yr) | C42: FCi,j,y | D42: mass or volume unit/year | E42: TOOL03
B43: the CO2 emission coefficient of fuel type i in year y (tCO2/mass or volume unit) | C43: COEFi,y | D43: tCO2/mass or volume unit | E43: TOOL03
...

Sheet ER Calc (by Waqar) 
F7: Option P. 1: High Technology Production Facility (Production Stage Emissions)
F9: Biochar Type | G9: Year | H9: Application Type | I9: Production Facility | J9: Molar mass of CO2 | K9: Molar mass of C | U9: Equation 2 | X9: Equation 4 | Y9: PEP,p,y = 0 | AB9: Equation 5 | AC9: Equation 3 | AD9: Equation 1 | AG9: Equation 12 | AI9: Equation 11 | AN9: Equation 13 | AO9: Equation 14 | AP9: Equation 15
F10: t | G10: y | H10: k | I10: p | L10: BEAS,y | M10: PESS,y | N10: BEC,y | O10: BED,y | P10: BESS,y | Q10: Mt,k,p,y | R10: Mp,y | S10: FCp,t,p | T10: PRde,k | U10: CCt,k,y | V10: PEDE,p,y | W10: PEDF,p,y | X10: PED,p,y | Y10: PEP,p,y | Z10: PECE,p,y | AA10: PECF,p,y | AB10: PEC,p,y | AC10: PEPS,t,p,y | AD10: ERPS,y | AE10: PEPF,k,y | AF10: PEPE,k,y | AG10: EP,t,k,y | AH10: Eap,t,k,y | AI10: PEAS,y | AJ10: LEas,y | AK10: LEbd,y | AL10: LEts,y | AM10: LEtap,y | AN10: LEy | AO10: ERSS,y | AP10: ERy
F12: Bamboo Pruning | G12: 1 | H12: Soil | I12: a | J12: 44 | K12: 12 | P12: =N12+O12 -> 0 | Q12: =2*5000 -> 10000 | R12: =Q12 -> 10000 | S12: 0.77 | T12: 0.89 | U12: =(Q12*S12*T12) -> 6853 | X12: =V12+W12 -> 0 | Y12: 0 | AB12: =Z12+AA12 -> 0 | AC12: =(X12+Y12+AB12)*(Q12/R12) -> 0 | AD12: =(U12*J12/K12)-AC12 -> 25127.667 | AG12: =AF12+AE12 -> 0 | AI12: =(AG12+AH12) -> 0 | AN12: =AJ12+AK12+AL12+AM12 -> 0 | AO12: =P11-M11 -> 0 | AP12: =AO12+AD12-AI12-AN12 -> 25127.667
F13: Paddy Straw | G13: 1 | H13: Soil | I13: a | J13: 44 | K13: 12 | P13: =N13+O13 -> 0 | Q13: =9.5*5000 -> 47500 | R13: =Q13 -> 47500 | S13: 0.49 | T13: 0.89 | U13: =(Q13*S13*T13) -> 20714.75 | X13: =V13+W13 -> 0 | Y13: 0 | AB13: =Z13+AA13 -> 0 | AC13: =(X13+Y13+AB13)*(Q13/R13) -> 0 | AD13: =(U13*J13/K13)-AC13 -> 75954.083 | AG13: =AF13+AE13 -> 0 | AI13: =(AG13+AH13) -> 0 | AN13: =AJ13+AK13+AL13+AM13 -> 0 | AO13: =P12-M12 -> 0 | AP13: =AO13+AD13-AI13-AN13 -> 75954.083
F14: Tree Pruning | G14: 1 | H14: Soil | I14: a | J14: 44 | K14: 12 | P14: =N14+O14 -> 0 | Q14: =1*5000 -> 5000 | R14: =Q14 -> 5000 | S14: 0.77 | T14: 0.89 | U14: =(Q14*S14*T14) -> 3426.5 | X14: =V14+W14 -> 0 | Y14: 0 | AB14: =Z14+AA14 -> 0 | AC14: =(X14+Y14+AB14)*(Q14/R14) -> 0 | AD14: =(U14*J14/K14)-AC14 -> 12563.833 | AG14: =AF14+AE14 -> 0 | AI14: =(AG14+AH14) -> 0 | AN14: =AJ14+AK14+AL14+AM14 -> 0 | AO14: =P13-M13 -> 0 | AP14: =AO14+AD14-AI14-AN14 -> 12563.833
R15: =SUM(Q12:Q14) -> 62500
F16: Paddy Straw | G16: 2 | H16: Soil | I16: a | J16: 44 | K16: 12 | P16: =N16+O16 -> 0 | Q16: =9.5*5000 -> 47500 | R16: =Q16 -> 47500 | S16: 0.49 | T16: 0.89 | U16: =(Q16*S16*T16) -> 20714.75 | X16: =V16+W16 -> 0 | Y16: 0 | AB16: =Z16+AA16 -> 0 | AC16: =(X16+Y16+AB16)*(Q16/R16) -> 0 | AD16: =(U16*J16/K16)-AC16 -> 75954.083 | AG16: =AF16+AE16 -> 0 | AI16: =(AG16+AH16) -> 0 | AN16: =AJ16+AK16+AL16+AM16 -> 0 | AO16: =P12-M12 -> 0 | AP16: =AO16+AD16-AI16-AN16 -> 75954.083
F17: Tree Pruning | G17: 2 | H17: Soil | I17: a | J17: 44 | K17: 12 | P17: =N17+O17 -> 0 | Q17: =1*5000 -> 5000 | R17: =Q17 -> 5000 | S17: 0.77 | T17: 0.89 | U17: =(Q17*S17*T17) -> 3426.5 | X17: =V17+W17 -> 0 | Y17: 0 | AB17: =Z17+AA17 -> 0 | AC17: =(X17+Y17+AB17)*(Q17/R17) -> 0 | AD17: =(U17*J17/K17)-AC17 -> 12563.833 | AG17: =AF17+AE17 -> 0 | AI17: =(AG17+AH17) -> 0 | AN17: =AJ17+AK17+AL17+AM17 -> 0 | AO17: =P16-M16 -> 0 | AP17: =AO17+AD17-AI17-AN17 -> 12563.833
F18: Bamboo Pruning | G18: 2 | H18: Soil | I18: a | J18: 44 | K18: 12 | P18: =N18+O18 -> 0 | Q18: =2*5000 -> 10000 | R18: =Q18 -> 10000 | S18: 0.77 | T18: 0.89 | U18: =(Q18*S18*T18) -> 6853 | X18: =V18+W18 -> 0 | Y18: 0 | AB18: =Z18+AA18 -> 0 | AC18: =(X18+Y18+AB18)*(Q18/R18) -> 0 | AD18: =(U18*J18/K18)-AC18 -> 25127.667 | AG18: =AF18+AE18 -> 0 | AI18: =(AG18+AH18) -> 0 | AN18: =AJ18+AK18+AL18+AM18 -> 0 | AO18: =P17-M17 -> 0 | AP18: =AO18+AD18-AI18-AN18 -> 25127.667
R19: =SUM(Q16:Q18) -> 62500
F20: Project hub: https://projecthub-uat.verra.org/project-description/1507 | AP20: =SUM(AP12:AP18) -> 227291.17
A28: Project ID | B28: NA
A29: Source | B29: ER calcs by Karina
A30: Tech tea, contact | B30: Waqar Ashiq | F30: Option P. 2: Low Technology Production Facility
A31: Test Date | B31: 45478
A32: Project Hub | B32: https://projecthub-uat.verra.org/project-description/1435
A33: Feedback | B33: Internal Testing and Feedback _ VM0044.xlsx | F33: Biochar Type | G33: Year | H33: Application Type | I33: Production Facility | J33: Kiln Type | K33: Molar mass of CO2 | L33: Molar mass of C | X33: Equation 8 | Y33: Equation 9 | Z33: Equation 10 | AE33: Equation 6 | AF33: Equation 7 | AG33: Equation 1 | AJ33: Equation 12 | AL33: Equation 11 | AQ33: Equation 13 | AR33: Equation 14 | AS33: Equation 15
F34: t | G34: y | H34: k | I34: p | M34: BEAS,y | N34: PESS,y | O34: BEC,y | P34: BED,y | Q34: BESS,y | R34: Fe | S34: GWPCH4 | T34: PECF,p,y | U34: PECE,p,y | V34: PEDF,p,y | W34: PEDE,p,y | X34: PED,p,y | Y34: PEP,p,y | Z34: PEC,p,y | AA34: Mt,k,p,y | AB34: Mp,y | AC34: FCp,t,p | AD34: PRde,k | AE34: CCt,k,y | AF34: PEPS,t, p,y | AG34: ERPS,y | AH34: PEPF,k,y | AI34: PEPE,k,y | AJ34: EP,t,k,y | AK34: Eap,t,k,y | AL34: PEAS,y | AM34: LEas,y | AN34: LEbd,y | AO34: LEts,y | AP34: LEtap,y | AQ34: LEy | AR34: ERSS,y | AS34: ERy
F35: Paddy Straw | G35: 1 | H35: Soil | I35: a | J35: a | K35: 44 | L35: 12 | Q35: =O35+P35 -> 0 | R35: 0.049 | S35: 28 | T35: 0 | X35: =W35+V35 -> 0 | Y35: =(R35*S35*AA35) -> 65170 | Z35: =U35+T35 -> 0 | AA35: =9.5*5000 -> 47500 | AB35: =AA35 -> 47500 | AC35: 0.49 | AD35: 0.89 | AE35: =(AA35*AC35*AD35) -> 20714.75 | AF35: =($X$38+$Y$38+$Z$38)*(AA35/$AB$38) -> 65170 | AG35: =(AE35*K35/L35)-AF35 -> 10784.083 | AJ35: =AI35+AH35 -> 0 | AL35: =(AJ35+AK35) -> 0 | AQ35: =AM35+AN35+AO35+AP35 -> 0 | AR35: =Q35-N35 -> 0 | AS35: =AR35+AG35-AL35-AQ35 -> 10784.083
F36: Tree Pruning | G36: 1 | H36: Soil | I36: a | J36: a | K36: 44 | L36: 12 | Q36: =O36+P36 -> 0 | R36: 0.049 | S36: 28 | T36: 0 | X36: =W36+V36 -> 0 | Y36: =(R36*S36*AA36) -> 6860 | Z36: =U36+T36 -> 0 | AA36: =1*5000 -> 5000 | AB36: =AA36 -> 5000 | AC36: 0.77 | AD36: 0.89 | AE36: =(AA36*AC36*AD36) -> 3426.5 | AF36: =($X$38+$Y$38+$Z$38)*(AA36/$AB$38) -> 6860 | AG36: =(AE36*K36/L36)-AF36 -> 5703.8333 | AJ36: =AI36+AH36 -> 0 | AL36: =(AJ36+AK36) -> 0 | AQ36: =AM36+AN36+AO36+AP36 -> 0 | AR36: =Q36-N36 -> 0 | AS36: =AR36+AG36-AL36-AQ36 -> 5703.8333
F37: Bamboo Pruning | G37: 1 | H37: Soil | I37: a | J37: a | K37: 44 | L37: 12 | Q37: =O37+P37 -> 0 | R37: 0.049 | S37: 28 | T37: 0 | X37: =W37+V37 -> 0 | Y37: =(R37*S37*AA37) -> 13720 | Z37: =U37+T37 -> 0 | AA37: =2*5000 -> 10000 | AB37: =AA37 -> 10000 | AC37: 0.77 | AD37: 0.89 | AE37: =(AA37*AC37*AD37) -> 6853 | AF37: =($X$38+$Y$38+$Z$38)*(AA37/$AB$38) -> 13720 | AG37: =(AE37*K37/L37)-AF37 -> 11407.667 | AJ37: =AI37+AH37 -> 0 | AL37: =(AJ37+AK37) -> 0 | AQ37: =AM37+AN37+AO37+AP37 -> 0 | AR37: =Q37-N37 -> 0 | AS37: =AR37+AG37-AL37-AQ37 -> 11407.667
F38: Sub-total | X38: =SUM(X35:X37) -> 0 | Y38: =SUM(Y35:Y37) -> 85750 | Z38: =SUM(Z35:Z37) -> 0 | AA38: =SUM(AA35:AA37) -> 62500 | AB38: =SUM(AB35:AB37) -> 62500 | AE38: =SUM(AE35:AE37) -> 30994.25 | AF38: =SUM(AF35:AF37) -> 85750 | AS38: =SUM(AS35:AS37) -> 27895.583
F39: Paddy Straw | G39: 2 | H39: Soil | I39: a | J39: a | K39: 44 | L39: 12 | Q39: =O39+P39 -> 0 | R39: 0.049 | S39: 28 | T39: 0 | X39: =W39+V39 -> 0 | Y39: =(R39*S39*AA39) -> 65170 | Z39: =U39+T39 -> 0 | AA39: =9.5*5000 -> 47500 | AB39: =AA39 -> 47500 | AC39: 0.49 | AD39: 0.89 | AE39: =(AA39*AC39*AD39) -> 20714.75 | AF39: =($X$42+$Y$42+$Z$42)*(AA39/$AB$42) -> 65170 | AG39: =(AE39*K39/L39)-AF39 -> 10784.083 | AJ39: =AI39+AH39 -> 0 | AL39: =(AJ39+AK39) -> 0 | AQ39: =AM39+AN39+AO39+AP39 -> 0 | AR39: =Q39-N39 -> 0 | AS39: =AR39+AG39-AL39-AQ39 -> 10784.083
F40: Tree Pruning | G40: 2 | H40: Soil | I40: a | J40: a | K40: 44 | L40: 12 | Q40: =O40+P40 -> 0 | R40: 0.049 | S40: 28 | T40: 0 | X40: =W40+V40 -> 0 | Y40: =(R40*S40*AA40) -> 6860 | Z40: =U40+T40 -> 0 | AA40: =1*5000 -> 5000 | AB40: =AA40 -> 5000 | AC40: 0.77 | AD40: 0.89 | AE40: =(AA40*AC40*AD40) -> 3426.5 | AF40: =($X$42+$Y$42+$Z$42)*(AA40/$AB$42) -> 6860 | AG40: =(AE40*K40/L40)-AF40 -> 5703.8333 | AJ40: =AI40+AH40 -> 0 | AL40: =(AJ40+AK40) -> 0 | AQ40: =AM40+AN40+AO40+AP40 -> 0 | AR40: =Q40-N40 -> 0 | AS40: =AR40+AG40-AL40-AQ40 -> 5703.8333
F41: Bamboo Pruning | G41: 2 | H41: Soil | I41: a | J41: a | K41: 44 | L41: 12 | Q41: =O41+P41 -> 0 | R41: 0.049 | S41: 28 | T41: 0 | X41: =W41+V41 -> 0 | Y41: =(R41*S41*AA41) -> 13720 | Z41: =U41+T41 -> 0 | AA41: =2*5000 -> 10000 | AB41: =AA41 -> 10000 | AC41: 0.77 | AD41: 0.89 | AE41: =(AA41*AC41*AD41) -> 6853 | AF41: =($X$42+$Y$42+$Z$42)*(AA41/$AB$42) -> 13720 | AG41: =(AE41*K41/L41)-AF41 -> 11407.667 | AJ41: =AI41+AH41 -> 0 | AL41: =(AJ41+AK41) -> 0 | AQ41: =AM41+AN41+AO41+AP41 -> 0 | AR41: =Q41-N41 -> 0 | AS41: =AR41+AG41-AL41-AQ41 -> 11407.667
F42: Sub-total | X42: =SUM(X39:X41) -> 0 | Y42: =SUM(Y39:Y41) -> 85750 | Z42: =SUM(Z39:Z41) -> 0 | AA42: =SUM(AA39:AA41) -> 62500 | AB42: =SUM(AB39:AB41) -> 62500 | AE42: =SUM(AE39:AE41) -> 30994.25 | AF42: =SUM(AF39:AF41) -> 85750 | AS42: =SUM(AS39:AS41) -> 27895.583
F43: Total | AS43: =SUM(AS42,AS38) -> 55791.167
F44: Project hub: https://projecthub-uat.verra.org/project-description/1506
AS47: =AS43*4 -> 223164.67
Z57: This table is same as table above, with equation 7 adjusted. Both producing same ER values
F58: Option P. 2: Low Technology Production Facility
F61: Biochar Type | G61: Year | H61: Application Type | I61: Production Facility | J61: Kiln Type | K61: Molar mass of CO2 | L61: Molar mass of C | X61: Equation 8 | Y61: Equation 9 | Z61: Equation 10 | AE61: Equation 6 | AF61: Equation 7 | AG61: Equation 1 | AJ61: Equation 12 | AL61: Equation 11 | AQ61: Equation 13 | AR61: Equation 14 | AS61: Equation 15
F62: t | G62: y | H62: k | I62: p | M62: BEAS,y | N62: PESS,y | O62: BEC,y | P62: BED,y | Q62: BESS,y | R62: Fe | S62: GWPCH4 | T62: PECF,p,y | U62: PECE,p,y | V62: PEDF,p,y | W62: PEDE,p,y | X62: PED,p,y | Y62: PEP,p,y | Z62: PEC,p,y | AA62: Mt,k,p,y | AB62: Mp,y | AC62: FCp,t,p | AD62: PRde,k | AE62: CCt,k,y | AF62: PEPS,t, p,y | AG62: ERPS,y | AH62: PEPF,k,y | AI62: PEPE,k,y | AJ62: EP,t,k,y | AK62: Eap,t,k,y | AL62: PEAS,y | AM62: LEas,y | AN62: LEbd,y | AO62: LEts,y | AP62: LEtap,y | AQ62: LEy | AR62: ERSS,y | AS62: ERy
F63: Paddy Straw | G63: 1 | H63: Soil | I63: a | J63: a | K63: 44 | L63: 12 | Q63: =O63+P63 -> 0 | R63: 0.049 | S63: 28 | T63: 0 | X63: =W63+V63 -> 0 | Y63: =(R63*S63*AA63) -> 65170 | Z63: =U63+T63 -> 0 | AA63: =9.5*5000 -> 47500 | AB63: =AA63 -> 47500 | AC63: 0.49 | AD63: 0.89 | AE63: =(AA63*AC63*AD63) -> 20714.75 | AF63: =(X63+Y63+Z63)*(AA63/AB63) -> 65170 | AG63: =(AE63*K63/L63)-AF63 -> 10784.083 | AJ63: =AI63+AH63 -> 0 | AL63: =(AJ63+AK63) -> 0 | AQ63: =AM63+AN63+AO63+AP63 -> 0 | AR63: =Q63-N63 -> 0 | AS63: =AR63+AG63-AL63-AQ63 -> 10784.083
F64: Tree Pruning | G64: 1 | H64: Soil | I64: a | J64: a | K64: 44 | L64: 12 | Q64: =O64+P64 -> 0 | R64: 0.049 | S64: 28 | T64: 0 | X64: =W64+V64 -> 0 | Y64: =(R64*S64*AA64) -> 6860 | Z64: =U64+T64 -> 0 | AA64: =1*5000 -> 5000 | AB64: =AA64 -> 5000 | AC64: 0.77 | AD64: 0.89 | AE64: =(AA64*AC64*AD64) -> 3426.5 | AF64: =(X64+Y64+Z64)*(AA64/AB64) -> 6860 | AG64: =(AE64*K64/L64)-AF64 -> 5703.8333 | AJ64: =AI64+AH64 -> 0 | AL64: =(AJ64+AK64) -> 0 | AQ64: =AM64+AN64+AO64+AP64 -> 0 | AR64: =Q64-N64 -> 0 | AS64: =AR64+AG64-AL64-AQ64 -> 5703.8333
F65: Bamboo Pruning | G65: 1 | H65: Soil | I65: a | J65: a | K65: 44 | L65: 12 | Q65: =O65+P65 -> 0 | R65: 0.049 | S65: 28 | T65: 0 | X65: =W65+V65 -> 0 | Y65: =(R65*S65*AA65) -> 13720 | Z65: =U65+T65 -> 0 | AA65: =2*5000 -> 10000 | AB65: =AA65 -> 10000 | AC65: 0.77 | AD65: 0.89 | AE65: =(AA65*AC65*AD65) -> 6853 | AF65: =(X65+Y65+Z65)*(AA65/AB65) -> 13720 | AG65: =(AE65*K65/L65)-AF65 -> 11407.667 | AJ65: =AI65+AH65 -> 0 | AL65: =(AJ65+AK65) -> 0 | AQ65: =AM65+AN65+AO65+AP65 -> 0 | AR65: =Q65-N65 -> 0 | AS65: =AR65+AG65-AL65-AQ65 -> 11407.667
F66: Paddy Straw | G66: 2 | H66: Soil | I66: a | J66: a | K66: 44 | L66: 12 | Q66: =O66+P66 -> 0 | R66: 0.049 | S66: 28 | T66: 0 | X66: =W66+V66 -> 0 | Y66: =(R66*S66*AA66) -> 65170 | Z66: =U66+T66 -> 0 | AA66: =9.5*5000 -> 47500 | AB66: =AA66 -> 47500 | AC66: 0.49 | AD66: 0.89 | AE66: =(AA66*AC66*AD66) -> 20714.75 | AF66: =(X66+Y66+Z66)*(AA66/AB66) -> 65170 | AG66: =(AE66*K66/L66)-AF66 -> 10784.083 | AJ66: =AI66+AH66 -> 0 | AL66: =(AJ66+AK66) -> 0 | AQ66: =AM66+AN66+AO66+AP66 -> 0 | AR66: =Q66-N66 -> 0 | AS66: =AR66+AG66-AL66-AQ66 -> 10784.083
F67: Tree Pruning | G67: 2 | H67: Soil | I67: a | J67: a | K67: 44 | L67: 12 | Q67: =O67+P67 -> 0 | R67: 0.049 | S67: 28 | T67: 0 | X67: =W67+V67 -> 0 | Y67: =(R67*S67*AA67) -> 6860 | Z67: =U67+T67 -> 0 | AA67: =1*5000 -> 5000 | AB67: =AA67 -> 5000 | AC67: 0.77 | AD67: 0.89 | AE67: =(AA67*AC67*AD67) -> 3426.5 | AF67: =(X67+Y67+Z67)*(AA67/AB67) -> 6860 | AG67: =(AE67*K67/L67)-AF67 -> 5703.8333 | AJ67: =AI67+AH67 -> 0 | AL67: =(AJ67+AK67) -> 0 | AQ67: =AM67+AN67+AO67+AP67 -> 0 | AR67: =Q67-N67 -> 0 | AS67: =AR67+AG67-AL67-AQ67 -> 5703.8333
F68: Bamboo Pruning | G68: 2 | H68: Soil | I68: a | J68: a | K68: 44 | L68: 12 | Q68: =O68+P68 -> 0 | R68: 0.049 | S68: 28 | T68: 0 | X68: =W68+V68 -> 0 | Y68: =(R68*S68*AA68) -> 13720 | Z68: =U68+T68 -> 0 | AA68: =2*5000 -> 10000 | AB68: =AA68 -> 10000 | AC68: 0.77 | AD68: 0.89 | AE68: =(AA68*AC68*AD68) -> 6853 | AF68: =(X68+Y68+Z68)*(AA68/AB68) -> 13720 | AG68: =(AE68*K68/L68)-AF68 -> 11407.667 | AJ68: =AI68+AH68 -> 0 | AL68: =(AJ68+AK68) -> 0 | AQ68: =AM68+AN68+AO68+AP68 -> 0 | AR68: =Q68-N68 -> 0 | AS68: =AR68+AG68-AL68-AQ68 -> 11407.667
...

Sheet Extended ER Calc (by Waqar) 
A4: Project ID | B4: NA
A5: Source | B5: ER calcs by Karina
A6: Tech tea, contact | B6: Waqar Ashiq
A7: Test Date | B7: 45478 | F7: Option P. 1: High Technology Production Facility (Production Stage Emissions)
A8: Project Hub | B8: https://projecthub-uat.verra.org/project-description/1435
A9: Feedback | B9: Internal Testing and Feedback _ VM0044.xlsx | F9: Biochar Type | G9: Year | H9: Application Type | I9: Production Facility | J9: Molar mass of CO2 | K9: Molar mass of C | U9: Equation 2 | X9: Equation 4 | Y9: PEP,p,y = 0 | AB9: Equation 5 | AC9: Equation 3 | AD9: Equation 1 | AG9: Equation 12 | AI9: Equation 11 | AN9: Equation 13 | AO9: Equation 14 | AP9: Equation 15
F10: t | G10: y | H10: k | I10: p | L10: BEAS,y | M10: PESS,y | N10: BEC,y | O10: BED,y | P10: BESS,y | Q10: Mt,k,p,y | R10: Mp,y | S10: FCp,t,p | T10: PRde,k | U10: CCt,k,y | V10: PEDE,p,y | W10: PEDF,p,y | X10: PED,p,y | Y10: PEP,p,y | Z10: PECE,p,y | AA10: PECF,p,y | AB10: PEC,p,y | AC10: PEPS,t,p,y | AD10: ERPS,y | AE10: PEPF,k,y | AF10: PEPE,k,y | AG10: EP,t,k,y | AH10: Eap,t,k,y | AI10: PEAS,y | AJ10: LEas,y | AK10: LEbd,y | AL10: LEts,y | AM10: LEtap,y | AN10: LEy | AO10: ERSS,y | AP10: ERy
F12: Bamboo Pruning | G12: 1 | H12: Soil | I12: a | J12: 44 | K12: 12 | P12: =N12+O12 -> 0 | Q12: =2*5000 -> 10000 | R12: =Q12 -> 10000 | S12: 0.77 | T12: 0.89 | U12: =(Q12*S12*T12) -> 6853 | V12: 21 | W12: 23 | X12: =V12+W12 -> 44 | Y12: 0 | Z12: 19 | AA12: 11 | AB12: =Z12+AA12 -> 30 | AC12: =($X$18+$Y$18+$AB$18)*(Q12/$R$18) -> 35.52 | AD12: =(U12*J12/K12)-AC12 -> 25092.147 | AE12: 17 | AF12: 12 | AG12: =AF12+AE12 -> 29 | AI12: =(AG12+AH12) -> 29 | AJ12: 0 | AK12: 10 | AL12: 13 | AM12: 9 | AN12: =AJ12+AK12+AL12+AM12 -> 32 | AO12: =P11-M11 -> 0 | AP12: =AO12+AD12-AI12-AN12 -> 25031.147
F13: Paddy Straw | G13: 1 | H13: Soil | I13: a | J13: 44 | K13: 12 | P13: =N13+O13 -> 0 | Q13: =9.5*5000 -> 47500 | R13: =Q13 -> 47500 | S13: 0.49 | T13: 0.89 | U13: =(Q13*S13*T13) -> 20714.75 | V13: 21 | W13: 23 | X13: =V13+W13 -> 44 | Y13: 0 | Z13: 19 | AA13: 11 | AB13: =Z13+AA13 -> 30 | AC13: =($X$18+$Y$18+$AB$18)*(Q13/$R$18) -> 168.72 | AD13: =(U13*J13/K13)-AC13 -> 75785.363 | AE13: 17 | AF13: 12 | AG13: =AF13+AE13 -> 29 | AI13: =(AG13+AH13) -> 29 | AJ13: 0 | AK13: 10 | AL13: 13 | AM13: 9 | AN13: =AJ13+AK13+AL13+AM13 -> 32 | AO13: =P12-M12 -> 0 | AP13: =AO13+AD13-AI13-AN13 -> 75724.363
F14: Tree Pruning | G14: 1 | H14: Soil | I14: a | J14: 44 | K14: 12 | P14: =N14+O14 -> 0 | Q14: =1*5000 -> 5000 | R14: =Q14 -> 5000 | S14: 0.77 | T14: 0.89 | U14: =(Q14*S14*T14) -> 3426.5 | V14: 21 | W14: 23 | X14: =V14+W14 -> 44 | Y14: 0 | Z14: 19 | AA14: 11 | AB14: =Z14+AA14 -> 30 | AC14: =($X$18+$Y$18+$AB$18)*(Q14/$R$18) -> 17.76 | AD14: =(U14*J14/K14)-AC14 -> 12546.073 | AE14: 17 | AF14: 12 | AG14: =AF14+AE14 -> 29 | AI14: =(AG14+AH14) -> 29 | AJ14: 0 | AK14: 10 | AL14: 13 | AM14: 9 | AN14: =AJ14+AK14+AL14+AM14 -> 32 | AO14: =P13-M13 -> 0 | AP14: =AO14+AD14-AI14-AN14 -> 12485.073
F15: Bamboo Pruning | G15: 1 | H15: Non-soil | I15: a | J15: 44 | K15: 12 | P15: =N15+O15 -> 0 | Q15: =2*5000 -> 10000 | R15: =Q15 -> 10000 | S15: 0.77 | T15: 0.92 | U15: =(Q15*S15*T15) -> 7084 | V15: 21 | W15: 23 | X15: =V15+W15 -> 44 | Y15: 0 | Z15: 19 | AA15: 11 | AB15: =Z15+AA15 -> 30 | AC15: =($X$18+$Y$18+$AB$18)*(Q15/$R$18) -> 35.52 | AD15: =(U15*J15/K15)-AC15 -> 25939.147 | AE15: 16 | AF15: 13 | AG15: =AF15+AE15 -> 29 | AI15: =(AG15+AH15) -> 29 | AJ15: 0 | AK15: 10 | AL15: 13 | AM15: 9 | AN15: =AJ15+AK15+AL15+AM15 -> 32 | AO15: =P14-M14 -> 0 | AP15: =AO15+AD15-AI15-AN15 -> 25878.147
F16: Paddy Straw | G16: 1 | H16: Non-soil | I16: a | J16: 44 | K16: 12 | P16: =N16+O16 -> 0 | Q16: =9.5*5000 -> 47500 | R16: =Q16 -> 47500 | S16: 0.49 | T16: 0.92 | U16: =(Q16*S16*T16) -> 21413 | V16: 21 | W16: 23 | X16: =V16+W16 -> 44 | Y16: 0 | Z16: 19 | AA16: 11 | AB16: =Z16+AA16 -> 30 | AC16: =($X$18+$Y$18+$AB$18)*(Q16/$R$18) -> 168.72 | AD16: =(U16*J16/K16)-AC16 -> 78345.613 | AE16: 16 | AF16: 13 | AG16: =AF16+AE16 -> 29 | AI16: =(AG16+AH16) -> 29 | AJ16: 0 | AK16: 10 | AL16: 13 | AM16: 9 | AN16: =AJ16+AK16+AL16+AM16 -> 32 | AO16: =P15-M15 -> 0 | AP16: =AO16+AD16-AI16-AN16 -> 78284.613
F17: Tree Pruning | G17: 1 | H17: Non-soil | I17: a | J17: 44 | K17: 12 | P17: =N17+O17 -> 0 | Q17: =1*5000 -> 5000 | R17: =Q17 -> 5000 | S17: 0.77 | T17: 0.92 | U17: =(Q17*S17*T17) -> 3542 | V17: 21 | W17: 23 | X17: =V17+W17 -> 44 | Y17: 0 | Z17: 19 | AA17: 11 | AB17: =Z17+AA17 -> 30 | AC17: =($X$18+$Y$18+$AB$18)*(Q17/$R$18) -> 17.76 | AD17: =(U17*J17/K17)-AC17 -> 12969.573 | AE17: 16 | AF17: 13 | AG17: =AF17+AE17 -> 29 | AI17: =(AG17+AH17) -> 29 | AJ17: 0 | AK17: 10 | AL17: 13 | AM17: 9 | AN17: =AJ17+AK17+AL17+AM17 -> 32 | AO17: =P16-M16 -> 0 | AP17: =AO17+AD17-AI17-AN17 -> 12908.573
R18: =SUM(R12:R17) -> 125000 | X18: =SUM(X12:X17) -> 264 | Y18: =SUM(Y12:Y17) -> 0 | AB18: =SUM(AB12:AB17) -> 180 | AC18: =SUM(AC12:AC17) -> 444
F19: Bamboo Pruning | G19: 1 | H19: Soil | I19: b | J19: 44 | K19: 12 | P19: =N19+O19 -> 0 | Q19: =2*5000 -> 10000 | R19: =Q19 -> 10000 | S19: 0.65 | T19: 0.89 | U19: =(Q19*S19*T19) -> 5785 | V19: 18 | W19: 20 | X19: =V19+W19 -> 38 | Y19: 0 | Z19: 16 | AA19: 9 | AB19: =Z19+AA19 -> 25 | AC19: =($X$25+$Y$25+$AB$25)*(Q19/$R$25) -> 30.24 | AD19: =(U19*J19/K19)-AC19 -> 21181.427 | AE19: 17 | AF19: 12 | AG19: =AF19+AE19 -> 29 | AI19: =(AG19+AH19) -> 29 | AJ19: 0 | AK19: 10 | AL19: 13 | AM19: 9 | AN19: =AJ19+AK19+AL19+AM19 -> 32 | AO19: =P17-M17 -> 0 | AP19: =AO19+AD19-AI19-AN19 -> 21120.427
F20: Paddy Straw | G20: 1 | H20: Soil | I20: b | J20: 44 | K20: 12 | P20: =N20+O20 -> 0 | Q20: =9.5*5000 -> 47500 | R20: =Q20 -> 47500 | S20: 0.72 | T20: 0.89 | U20: =(Q20*S20*T20) -> 30438 | V20: 18 | W20: 20 | X20: =V20+W20 -> 38 | Y20: 0 | Z20: 16 | AA20: 9 | AB20: =Z20+AA20 -> 25 | AC20: =($X$25+$Y$25+$AB$25)*(Q20/$R$25) -> 143.64 | AD20: =(U20*J20/K20)-AC20 -> 111462.36 | AE20: 17 | AF20: 12 | AG20: =AF20+AE20 -> 29 | AI20: =(AG20+AH20) -> 29 | AJ20: 0 | AK20: 10 | AL20: 13 | AM20: 9 | AN20: =AJ20+AK20+AL20+AM20 -> 32 | AO20: =P19-M19 -> 0 | AP20: =AO20+AD20-AI20-AN20 -> 111401.36
F21: Tree Pruning | G21: 1 | H21: Soil | I21: b | J21: 44 | K21: 12 | P21: =N21+O21 -> 0 | Q21: =1*5000 -> 5000 | R21: =Q21 -> 5000 | S21: 0.79 | T21: 0.89 | U21: =(Q21*S21*T21) -> 3515.5 | V21: 18 | W21: 20 | X21: =V21+W21 -> 38 | Y21: 0 | Z21: 16 | AA21: 9 | AB21: =Z21+AA21 -> 25 | AC21: =($X$25+$Y$25+$AB$25)*(Q21/$R$25) -> 15.12 | AD21: =(U21*J21/K21)-AC21 -> 12875.047 | AE21: 17 | AF21: 12 | AG21: =AF21+AE21 -> 29 | AI21: =(AG21+AH21) -> 29 | AJ21: 0 | AK21: 10 | AL21: 13 | AM21: 9 | AN21: =AJ21+AK21+AL21+AM21 -> 32 | AO21: =P20-M20 -> 0 | AP21: =AO21+AD21-AI21-AN21 -> 12814.047
F22: Bamboo Pruning | G22: 1 | H22: Non-soil | I22: b | J22: 44 | K22: 12 | P22: =N22+O22 -> 0 | Q22: =2*5000 -> 10000 | R22: =Q22 -> 10000 | S22: 0.65 | T22: 0.92 | U22: =(Q22*S22*T22) -> 5980 | V22: 18 | W22: 20 | X22: =V22+W22 -> 38 | Y22: 0 | Z22: 16 | AA22: 9 | AB22: =Z22+AA22 -> 25 | AC22: =($X$25+$Y$25+$AB$25)*(Q22/$R$25) -> 30.24 | AD22: =(U22*J22/K22)-AC22 -> 21896.427 | AE22: 16 | AF22: 13 | AG22: =AF22+AE22 -> 29 | AI22: =(AG22+AH22) -> 29 | AJ22: 0 | AK22: 10 | AL22: 13 | AM22: 9 | AN22: =AJ22+AK22+AL22+AM22 -> 32 | AO22: =P21-M21 -> 0 | AP22: =AO22+AD22-AI22-AN22 -> 21835.427
F23: Paddy Straw | G23: 1 | H23: Non-soil | I23: b | J23: 44 | K23: 12 | P23: =N23+O23 -> 0 | Q23: =9.5*5000 -> 47500 | R23: =Q23 -> 47500 | S23: 0.72 | T23: 0.92 | U23: =(Q23*S23*T23) -> 31464 | V23: 18 | W23: 20 | X23: =V23+W23 -> 38 | Y23: 0 | Z23: 16 | AA23: 9 | AB23: =Z23+AA23 -> 25 | AC23: =($X$25+$Y$25+$AB$25)*(Q23/$R$25) -> 143.64 | AD23: =(U23*J23/K23)-AC23 -> 115224.36 | AE23: 16 | AF23: 13 | AG23: =AF23+AE23 -> 29 | AI23: =(AG23+AH23) -> 29 | AJ23: 0 | AK23: 10 | AL23: 13 | AM23: 9 | AN23: =AJ23+AK23+AL23+AM23 -> 32 | AO23: =P22-M22 -> 0 | AP23: =AO23+AD23-AI23-AN23 -> 115163.36
F24: Tree Pruning | G24: 1 | H24: Non-soil | I24: b | J24: 44 | K24: 12 | P24: =N24+O24 -> 0 | Q24: =1*5000 -> 5000 | R24: =Q24 -> 5000 | S24: 0.79 | T24: 0.92 | U24: =(Q24*S24*T24) -> 3634 | V24: 18 | W24: 20 | X24: =V24+W24 -> 38 | Y24: 0 | Z24: 16 | AA24: 9 | AB24: =Z24+AA24 -> 25 | AC24: =($X$25+$Y$25+$AB$25)*(Q24/$R$25) -> 15.12 | AD24: =(U24*J24/K24)-AC24 -> 13309.547 | AE24: 16 | AF24: 13 | AG24: =AF24+AE24 -> 29 | AI24: =(AG24+AH24) -> 29 | AJ24: 0 | AK24: 10 | AL24: 13 | AM24: 9 | AN24: =AJ24+AK24+AL24+AM24 -> 32 | AO24: =P23-M23 -> 0 | AP24: =AO24+AD24-AI24-AN24 -> 13248.547
R25: =SUM(R19:R24) -> 125000 | X25: =SUM(X19:X24) -> 228 | Y25: =SUM(Y19:Y24) -> 0 | AB25: =SUM(AB19:AB24) -> 150 | AC25: =SUM(AC19:AC24) -> 378
F26: Bamboo Pruning | G26: 2 | H26: Soil | I26: a | J26: 44 | K26: 12 | P26: =N26+O26 -> 0 | Q26: =2*5000 -> 10000 | R26: =Q26 -> 10000 | S26: 0.77 | T26: 0.89 | U26: =(Q26*S26*T26) -> 6853 | V26: 12 | W26: 14 | X26: =V26+W26 -> 26 | Y26: 0 | Z26: 11 | AA26: 6 | AB26: =Z26+AA26 -> 17 | AC26: =($X$32+$Y$32+$AB$32)*(Q26/$R$32) -> 20.64 | AD26: =(U26*J26/K26)-AC26 -> 25107.027 | AE26: 15 | AF26: 19 | AG26: =AF26+AE26 -> 34 | AI26: =(AG26+AH26) -> 34 | AJ26: 0 | AK26: 11 | AL26: 19 | AM26: 7 | AN26: =AJ26+AK26+AL26+AM26 -> 37 | AO26: =P12-M12 -> 0 | AP26: =AO26+AD26-AI26-AN26 -> 25036.027
F27: Paddy Straw | G27: 2 | H27: Soil | I27: a | J27: 44 | K27: 12 | P27: =N27+O27 -> 0 | Q27: =9.5*5000 -> 47500 | R27: =Q27 -> 47500 | S27: 0.49 | T27: 0.89 | U27: =(Q27*S27*T27) -> 20714.75 | V27: 12 | W27: 14 | X27: =V27+W27 -> 26 | Y27: 0 | Z27: 11 | AA27: 6 | AB27: =Z27+AA27 -> 17 | AC27: =($X$32+$Y$32+$AB$32)*(Q27/$R$32) -> 98.04 | AD27: =(U27*J27/K27)-AC27 -> 75856.043 | AE27: 15 | AF27: 19 | AG27: =AF27+AE27 -> 34 | AI27: =(AG27+AH27) -> 34 | AJ27: 0 | AK27: 11 | AL27: 19 | AM27: 7 | AN27: =AJ27+AK27+AL27+AM27 -> 37 | AO27: =P26-M26 -> 0 | AP27: =AO27+AD27-AI27-AN27 -> 75785.043
F28: Tree Pruning | G28: 2 | H28: Soil | I28: a | J28: 44 | K28: 12 | P28: =N28+O28 -> 0 | Q28: =1*5000 -> 5000 | R28: =Q28 -> 5000 | S28: 0.77 | T28: 0.89 | U28: =(Q28*S28*T28) -> 3426.5 | V28: 12 | W28: 14 | X28: =V28+W28 -> 26 | Y28: 0 | Z28: 11 | AA28: 6 | AB28: =Z28+AA28 -> 17 | AC28: =($X$32+$Y$32+$AB$32)*(Q28/$R$32) -> 10.32 | AD28: =(U28*J28/K28)-AC28 -> 12553.513 | AE28: 15 | AF28: 19 | AG28: =AF28+AE28 -> 34 | AI28: =(AG28+AH28) -> 34 | AJ28: 0 | AK28: 11 | AL28: 19 | AM28: 7 | AN28: =AJ28+AK28+AL28+AM28 -> 37 | AO28: =P27-M27 -> 0 | AP28: =AO28+AD28-AI28-AN28 -> 12482.513
F29: Bamboo Pruning | G29: 2 | H29: Non-soil | I29: a | J29: 44 | K29: 12 | P29: =N29+O29 -> 0 | Q29: =2*5000 -> 10000 | R29: =Q29 -> 10000 | S29: 0.77 | T29: 0.92 | U29: =(Q29*S29*T29) -> 7084 | V29: 12 | W29: 14 | X29: =V29+W29 -> 26 | Y29: 0 | Z29: 11 | AA29: 6 | AB29: =Z29+AA29 -> 17 | AC29: =($X$32+$Y$32+$AB$32)*(Q29/$R$32) -> 20.64 | AD29: =(U29*J29/K29)-AC29 -> 25954.027 | AE29: 24 | AF29: 11 | AG29: =AF29+AE29 -> 35 | AI29: =(AG29+AH29) -> 35 | AJ29: 0 | AK29: 11 | AL29: 19 | AM29: 7 | AN29: =AJ29+AK29+AL29+AM29 -> 37 | AO29: =P15-M15 -> 0 | AP29: =AO29+AD29-AI29-AN29 -> 25882.027
F30: Paddy Straw | G30: 2 | H30: Non-soil | I30: a | J30: 44 | K30: 12 | P30: =N30+O30 -> 0 | Q30: =9.5*5000 -> 47500 | R30: =Q30 -> 47500 | S30: 0.49 | T30: 0.92 | U30: =(Q30*S30*T30) -> 21413 | V30: 12 | W30: 14 | X30: =V30+W30 -> 26 | Y30: 0 | Z30: 11 | AA30: 6 | AB30: =Z30+AA30 -> 17 | AC30: =($X$32+$Y$32+$AB$32)*(Q30/$R$32) -> 98.04 | AD30: =(U30*J30/K30)-AC30 -> 78416.293 | AE30: 24 | AF30: 11 | AG30: =AF30+AE30 -> 35 | AI30: =(AG30+AH30) -> 35 | AJ30: 0 | AK30: 11 | AL30: 19 | AM30: 7 | AN30: =AJ30+AK30+AL30+AM30 -> 37 | AO30: =P29-M29 -> 0 | AP30: =AO30+AD30-AI30-AN30 -> 78344.293
F31: Tree Pruning | G31: 2 | H31: Non-soil | I31: a | J31: 44 | K31: 12 | P31: =N31+O31 -> 0 | Q31: =1*5000 -> 5000 | R31: =Q31 -> 5000 | S31: 0.77 | T31: 0.92 | U31: =(Q31*S31*T31) -> 3542 | V31: 12 | W31: 14 | X31: =V31+W31 -> 26 | Y31: 0 | Z31: 11 | AA31: 6 | AB31: =Z31+AA31 -> 17 | AC31: =($X$32+$Y$32+$AB$32)*(Q31/$R$32) -> 10.32 | AD31: =(U31*J31/K31)-AC31 -> 12977.013 | AE31: 24 | AF31: 11 | AG31: =AF31+AE31 -> 35 | AI31: =(AG31+AH31) -> 35 | AJ31: 0 | AK31: 11 | AL31: 19 | AM31: 7 | AN31: =AJ31+AK31+AL31+AM31 -> 37 | AO31: =P30-M30 -> 0 | AP31: =AO31+AD31-AI31-AN31 -> 12905.013
R32: =SUM(R26:R31) -> 125000 | X32: =SUM(X26:X31) -> 156 | Y32: =SUM(Y26:Y31) -> 0 | AB32: =SUM(AB26:AB31) -> 102 | AC32: =SUM(AC26:AC31) -> 258
F33: Bamboo Pruning | G33: 2 | H33: Soil | I33: b | J33: 44 | K33: 12 | P33: =N33+O33 -> 0 | Q33: =2*5000 -> 10000 | R33: =Q33 -> 10000 | S33: 0.65 | T33: 0.89 | U33: =(Q33*S33*T33) -> 5785 | V33: 8 | W33: 9 | X33: =V33+W33 -> 17 | Y33: 0 | Z33: 7 | AA33: 4 | AB33: =Z33+AA33 -> 11 | AC33: =($X$39+$Y$39+$AB$39)*(Q33/$R$39) -> 13.44 | AD33: =(U33*J33/K33)-AC33 -> 21198.227 | AE33: 15 | AF33: 19 | AG33: =AF33+AE33 -> 34 | AI33: =(AG33+AH33) -> 34 | AJ33: 0 | AK33: 11 | AL33: 19 | AM33: 7 | AN33: =AJ33+AK33+AL33+AM33 -> 37 | AO33: =P19-M19 -> 0 | AP33: =AO33+AD33-AI33-AN33 -> 21127.227
F34: Paddy Straw | G34: 2 | H34: Soil | I34: b | J34: 44 | K34: 12 | P34: =N34+O34 -> 0 | Q34: =9.5*5000 -> 47500 | R34: =Q34 -> 47500 | S34: 0.72 | T34: 0.89 | U34: =(Q34*S34*T34) -> 30438 | V34: 8 | W34: 9 | X34: =V34+W34 -> 17 | Y34: 0 | Z34: 7 | AA34: 4 | AB34: =Z34+AA34 -> 11 | AC34: =($X$39+$Y$39+$AB$39)*(Q34/$R$39) -> 63.84 | AD34: =(U34*J34/K34)-AC34 -> 111542.16 | AE34: 15 | AF34: 19 | AG34: =AF34+AE34 -> 34 | AI34: =(AG34+AH34) -> 34 | AJ34: 0 | AK34: 11 | AL34: 19 | AM34: 7 | AN34: =AJ34+AK34+AL34+AM34 -> 37 | AO34: =P33-M33 -> 0 | AP34: =AO34+AD34-AI34-AN34 -> 111471.16
F35: Tree Pruning | G35: 2 | H35: Soil | I35: b | J35: 44 | K35: 12 | P35: =N35+O35 -> 0 | Q35: =1*5000 -> 5000 | R35: =Q35 -> 5000 | S35: 0.79 | T35: 0.89 | U35: =(Q35*S35*T35) -> 3515.5 | V35: 8 | W35: 9 | X35: =V35+W35 -> 17 | Y35: 0 | Z35: 7 | AA35: 4 | AB35: =Z35+AA35 -> 11 | AC35: =($X$39+$Y$39+$AB$39)*(Q35/$R$39) -> 6.72 | AD35: =(U35*J35/K35)-AC35 -> 12883.447 | AE35: 15 | AF35: 19 | AG35: =AF35+AE35 -> 34 | AI35: =(AG35+AH35) -> 34 | AJ35: 0 | AK35: 11 | AL35: 19 | AM35: 7 | AN35: =AJ35+AK35+AL35+AM35 -> 37 | AO35: =P34-M34 -> 0 | AP35: =AO35+AD35-AI35-AN35 -> 12812.447
F36: Bamboo Pruning | G36: 2 | H36: Non-soil | I36: b | J36: 44 | K36: 12 | P36: =N36+O36 -> 0 | Q36: =2*5000 -> 10000 | R36: =Q36 -> 10000 | S36: 0.65 | T36: 0.92 | U36: =(Q36*S36*T36) -> 5980 | V36: 8 | W36: 9 | X36: =V36+W36 -> 17 | Y36: 0 | Z36: 7 | AA36: 4 | AB36: =Z36+AA36 -> 11 | AC36: =($X$39+$Y$39+$AB$39)*(Q36/$R$39) -> 13.44 | AD36: =(U36*J36/K36)-AC36 -> 21913.227 | AE36: 24 | AF36: 11 | AG36: =AF36+AE36 -> 35 | AI36: =(AG36+AH36) -> 35 | AJ36: 0 | AK36: 11 | AL36: 19 | AM36: 7 | AN36: =AJ36+AK36+AL36+AM36 -> 37 | AO36: =P22-M22 -> 0 | AP36: =AO36+AD36-AI36-AN36 -> 21841.227
F37: Paddy Straw | G37: 2 | H37: Non-soil | I37: b | J37: 44 | K37: 12 | P37: =N37+O37 -> 0 | Q37: =9.5*5000 -> 47500 | R37: =Q37 -> 47500 | S37: 0.72 | T37: 0.92 | U37: =(Q37*S37*T37) -> 31464 | V37: 8 | W37: 9 | X37: =V37+W37 -> 17 | Y37: 0 | Z37: 7 | AA37: 4 | AB37: =Z37+AA37 -> 11 | AC37: =($X$39+$Y$39+$AB$39)*(Q37/$R$39) -> 63.84 | AD37: =(U37*J37/K37)-AC37 -> 115304.16 | AE37: 24 | AF37: 11 | AG37: =AF37+AE37 -> 35 | AI37: =(AG37+AH37) -> 35 | AJ37: 0 | AK37: 11 | AL37: 19 | AM37: 7 | AN37: =AJ37+AK37+AL37+AM37 -> 37 | AO37: =P36-M36 -> 0 | AP37: =AO37+AD37-AI37-AN37 -> 115232.16
F38: Tree Pruning | G38: 2 | H38: Non-soil | I38: b | J38: 44 | K38: 12 | P38: =N38+O38 -> 0 | Q38: =1*5000 -> 5000 | R38: =Q38 -> 5000 | S38: 0.79 | T38: 0.92 | U38: =(Q38*S38*T38) -> 3634 | V38: 8 | W38: 9 | X38: =V38+W38 -> 17 | Y38: 0 | Z38: 7 | AA38: 4 | AB38: =Z38+AA38 -> 11 | AC38: =($X$39+$Y$39+$AB$39)*(Q38/$R$39) -> 6.72 | AD38: =(U38*J38/K38)-AC38 -> 13317.947 | AE38: 24 | AF38: 11 | AG38: =AF38+AE38 -> 35 | AI38: =(AG38+AH38) -> 35 | AJ38: 0 | AK38: 11 | AL38: 19 | AM38: 7 | AN38: =AJ38+AK38+AL38+AM38 -> 37 | AO38: =P37-M37 -> 0 | AP38: =AO38+AD38-AI38-AN38 -> 13245.947
R39: =SUM(R33:R38) -> 125000 | X39: =SUM(X33:X38) -> 102 | Y39: =SUM(Y33:Y38) -> 0 | AB39: =SUM(AB33:AB38) -> 66 | AC39: =SUM(AC33:AC38) -> 168
F40: https://projecthub-uat.verra.org/project-description/1601 | AP40: =SUM(AP12:AP38) -> 1052060.2
F41: https://projecthub-uat2.verra.org/project-description/13
F43: Option P. 2: Low Technology Production Facility
AV44: =AP40+AS78 -> 1275224.8
AV45: =AQ41+AS80 -> 0
...

Sheet Extended ER Calc2 (Waqar)
A4: Project ID | B4: NA
A5: Source | B5: ER calcs by Karina
A6: Tech tea, contact | B6: Waqar Ashiq
A7: Test Date | B7: 45478 | F7: Option P. 1: High Technology Production Facility (Production Stage Emissions)
A8: Project Hub | B8: https://projecthub-uat.verra.org/project-description/1435
A9: Feedback | B9: Internal Testing and Feedback _ VM0044.xlsx | F9: Biochar Type | G9: Year | H9: Application Type | I9: Production Facility | J9: Molar mass of CO2 | K9: Molar mass of C | U9: Equation 2 | X9: Equation 4 | Y9: PEP,p,y = 0 | AB9: Equation 5 | AC9: Equation 3 | AD9: Equation 1 | AG9: Equation 12 | AI9: Equation 11 | AN9: Equation 13 | AO9: Equation 14 | AP9: Equation 15
F10: t | G10: y | H10: k | I10: p | L10: BEAS,y | M10: PESS,y | N10: BEC,y | O10: BED,y | P10: BESS,y | Q10: Mt,k,p,y | R10: Mp,y | S10: FCp,t,p | T10: PRde,k | U10: CCt,k,y | V10: PEDE,p,y | W10: PEDF,p,y | X10: PED,p,y | Y10: PEP,p,y | Z10: PECE,p,y | AA10: PECF,p,y | AB10: PEC,p,y | AC10: PEPS,t,p,y | AD10: ERPS,y | AE10: PEPF,k,y | AF10: PEPE,k,y | AG10: EP,t,k,y | AH10: Eap,t,k,y | AI10: PEAS,y | AJ10: LEas,y | AK10: LEbd,y | AL10: LEts,y | AM10: LEtap,y | AN10: LEy | AO10: ERSS,y | AP10: ERy
F12: Bamboo Pruning | G12: 1 | H12: Soil | I12: a | J12: 44 | K12: 12 | P12: =N12+O12 -> 0 | Q12: =2*5000 -> 10000 | R12: =Q12 -> 10000 | S12: 0.77 | T12: 0.89 | U12: =(Q12*S12*T12) -> 6853 | V12: 1 | W12: 1 | X12: =V12+W12 -> 2 | Y12: 0 | Z12: 1 | AA12: 1 | AB12: =Z12+AA12 -> 2 | AC12: =($X$19+$Y$19+$AB$19)*(Q12/$R$19) -> 1.92 | AD12: =(U12*J12/K12)-AC12 -> 25125.747 | AE12: 1 | AF12: 1 | AG12: =AF12+AE12 -> 2 | AH12: 1 | AI12: =(AG12+AH12) -> 3 | AJ12: 0 | AK12: 1 | AL12: 1 | AM12: 1 | AN12: =AJ12+AK12+AL12+AM12 -> 3 | AO12: =P11-M11 -> 0 | AP12: =AO12+AD12-AI12-AN12 -> 25119.747
F13: Paddy Straw | G13: 1 | H13: Soil | I13: a | J13: 44 | K13: 12 | P13: =N13+O13 -> 0 | Q13: =9.5*5000 -> 47500 | R13: =Q13 -> 47500 | S13: 0.49 | T13: 0.89 | U13: =(Q13*S13*T13) -> 20714.75 | V13: 1 | W13: 1 | X13: =V13+W13 -> 2 | Y13: 0 | Z13: 1 | AA13: 1 | AB13: =Z13+AA13 -> 2 | AC13: =($X$19+$Y$19+$AB$19)*(Q13/$R$19) -> 9.12 | AD13: =(U13*J13/K13)-AC13 -> 75944.963 | AE13: 1 | AF13: 1 | AG13: =AF13+AE13 -> 2 | AH13: 1 | AI13: =(AG13+AH13) -> 3 | AJ13: 0 | AK13: 1 | AL13: 1 | AM13: 1 | AN13: =AJ13+AK13+AL13+AM13 -> 3 | AO13: =P12-M12 -> 0 | AP13: =AO13+AD13-AI13-AN13 -> 75938.963
F14: Tree Pruning | G14: 1 | H14: Soil | I14: a | J14: 44 | K14: 12 | P14: =N14+O14 -> 0 | Q14: =1*5000 -> 5000 | R14: =Q14 -> 5000 | S14: 0.77 | T14: 0.89 | U14: =(Q14*S14*T14) -> 3426.5 | V14: 1 | W14: 1 | X14: =V14+W14 -> 2 | Y14: 0 | Z14: 1 | AA14: 1 | AB14: =Z14+AA14 -> 2 | AC14: =($X$19+$Y$19+$AB$19)*(Q14/$R$19) -> 0.96 | AD14: =(U14*J14/K14)-AC14 -> 12562.873 | AE14: 1 | AF14: 1 | AG14: =AF14+AE14 -> 2 | AH14: 1 | AI14: =(AG14+AH14) -> 3 | AJ14: 0 | AK14: 1 | AL14: 1 | AM14: 1 | AN14: =AJ14+AK14+AL14+AM14 -> 3 | AO14: =P13-M13 -> 0 | AP14: =AO14+AD14-AI14-AN14 -> 12556.873
AE15: =SUM(AE12:AE14) -> 3 | AF15: =SUM(AF12:AF14) -> 3 | AG15: =SUM(AG12:AG14) -> 6
F16: Bamboo Pruning | G16: 1 | H16: Non-soil | I16: a | J16: 44 | K16: 12 | P16: =N16+O16 -> 0 | Q16: =2*5000 -> 10000 | R16: =Q16 -> 10000 | S16: 0.77 | T16: 0.89 | U16: =(Q16*S16*T16) -> 6853 | V16: 1 | W16: 1 | X16: =V16+W16 -> 2 | Y16: 0 | Z16: 1 | AA16: 1 | AB16: =Z16+AA16 -> 2 | AC16: =($X$19+$Y$19+$AB$19)*(Q16/$R$19) -> 1.92 | AD16: =(U16*J16/K16)-AC16 -> 25125.747 | AE16: 1.5 | AF16: 1.5 | AG16: =AF16+AE16 -> 3 | AH16: 1.5 | AI16: =(AG16+AH16) -> 4.5 | AJ16: 0 | AK16: 1 | AL16: 1 | AM16: 1 | AN16: =AJ16+AK16+AL16+AM16 -> 3 | AO16: =P14-M14 -> 0 | AP16: =AO16+AD16-AI16-AN16 -> 25118.247
F17: Paddy Straw | G17: 1 | H17: Non-soil | I17: a | J17: 44 | K17: 12 | P17: =N17+O17 -> 0 | Q17: =9.5*5000 -> 47500 | R17: =Q17 -> 47500 | S17: 0.49 | T17: 0.89 | U17: =(Q17*S17*T17) -> 20714.75 | V17: 1 | W17: 1 | X17: =V17+W17 -> 2 | Y17: 0 | Z17: 1 | AA17: 1 | AB17: =Z17+AA17 -> 2 | AC17: =($X$19+$Y$19+$AB$19)*(Q17/$R$19) -> 9.12 | AD17: =(U17*J17/K17)-AC17 -> 75944.963 | AE17: 1.5 | AF17: 1.5 | AG17: =AF17+AE17 -> 3 | AH17: 1.5 | AI17: =(AG17+AH17) -> 4.5 | AJ17: 0 | AK17: 1 | AL17: 1 | AM17: 1 | AN17: =AJ17+AK17+AL17+AM17 -> 3 | AO17: =P16-M16 -> 0 | AP17: =AO17+AD17-AI17-AN17 -> 75937.463
F18: Tree Pruning | G18: 1 | H18: Non-soil | I18: a | J18: 44 | K18: 12 | P18: =N18+O18 -> 0 | Q18: =1*5000 -> 5000 | R18: =Q18 -> 5000 | S18: 0.77 | T18: 0.89 | U18: =(Q18*S18*T18) -> 3426.5 | V18: 1 | W18: 1 | X18: =V18+W18 -> 2 | Y18: 0 | Z18: 1 | AA18: 1 | AB18: =Z18+AA18 -> 2 | AC18: =($X$19+$Y$19+$AB$19)*(Q18/$R$19) -> 0.96 | AD18: =(U18*J18/K18)-AC18 -> 12562.873 | AE18: 1.5 | AF18: 1.5 | AG18: =AF18+AE18 -> 3 | AH18: 1.5 | AI18: =(AG18+AH18) -> 4.5 | AJ18: 0 | AK18: 1 | AL18: 1 | AM18: 1 | AN18: =AJ18+AK18+AL18+AM18 -> 3 | AO18: =P17-M17 -> 0 | AP18: =AO18+AD18-AI18-AN18 -> 12555.373
R19: =SUM(R12:R18) -> 125000 | V19: =SUM(V12:V18) -> 6 | W19: =SUM(W12:W18) -> 6 | X19: =SUM(X12:X18) -> 12 | Y19: =SUM(Y12:Y18) -> 0 | Z19: =SUM(Z12:Z18) -> 6 | AA19: =SUM(AA12:AA18) -> 6 | AB19: =SUM(AB12:AB18) -> 12 | AC19: =SUM(AC12:AC18) -> 24 | AD19: =SUM(AD12:AD18) -> 227267.17 | AE19: =SUM(AE16:AE18) -> 4.5 | AF19: =SUM(AF16:AF18) -> 4.5 | AG19: =SUM(AG16:AG18) -> 9 | AJ19: =SUM(AJ16:AJ18) -> 0 | AK19: =SUM(AK16:AK18) -> 3 | AL19: =SUM(AL16:AL18) -> 3 | AM19: =SUM(AM16:AM18) -> 3 | AN19: =SUM(AN12:AN18) -> 18 | AO19: =SUM(AO12:AO18) -> 0
F20: Bamboo Pruning | G20: 1 | H20: Soil | I20: b | J20: 44 | K20: 12 | P20: =N20+O20 -> 0 | Q20: =2*5000 -> 10000 | R20: =Q20 -> 10000 | S20: 0.77 | T20: 0.89 | U20: =(Q20*S20*T20) -> 6853 | V20: 2 | W20: 2 | X20: =V20+W20 -> 4 | Y20: 0 | Z20: 2 | AA20: 2 | AB20: =Z20+AA20 -> 4 | AC20: =($X$27+$Y$27+$AB$27)*(Q20/$R$27) -> 3.84 | AD20: =(U20*J20/K20)-AC20 -> 25123.827 | AE20: 1 | AF20: 1 | AG20: =AF20+AE20 -> 2 | AH20: 1 | AI20: =(AG20+AH20) -> 3 | AJ20: 0 | AK20: 1 | AL20: 1 | AM20: 1 | AN20: =AJ20+AK20+AL20+AM20 -> 3 | AO20: =P18-M18 -> 0 | AP20: =AO20+AD20-AI20-AN20 -> 25117.827
F21: Paddy Straw | G21: 1 | H21: Soil | I21: b | J21: 44 | K21: 12 | P21: =N21+O21 -> 0 | Q21: =9.5*5000 -> 47500 | R21: =Q21 -> 47500 | S21: 0.49 | T21: 0.89 | U21: =(Q21*S21*T21) -> 20714.75 | V21: 2 | W21: 2 | X21: =V21+W21 -> 4 | Y21: 0 | Z21: 2 | AA21: 2 | AB21: =Z21+AA21 -> 4 | AC21: =($X$27+$Y$27+$AB$27)*(Q21/$R$27) -> 18.24 | AD21: =(U21*J21/K21)-AC21 -> 75935.843 | AE21: 1 | AF21: 1 | AG21: =AF21+AE21 -> 2 | AH21: 1 | AI21: =(AG21+AH21) -> 3 | AJ21: 0 | AK21: 1 | AL21: 1 | AM21: 1 | AN21: =AJ21+AK21+AL21+AM21 -> 3 | AO21: =P20-M20 -> 0 | AP21: =AO21+AD21-AI21-AN21 -> 75929.843
F22: Tree Pruning | G22: 1 | H22: Soil | I22: b | J22: 44 | K22: 12 | P22: =N22+O22 -> 0 | Q22: =1*5000 -> 5000 | R22: =Q22 -> 5000 | S22: 0.77 | T22: 0.89 | U22: =(Q22*S22*T22) -> 3426.5 | V22: 2 | W22: 2 | X22: =V22+W22 -> 4 | Y22: 0 | Z22: 2 | AA22: 2 | AB22: =Z22+AA22 -> 4 | AC22: =($X$27+$Y$27+$AB$27)*(Q22/$R$27) -> 1.92 | AD22: =(U22*J22/K22)-AC22 -> 12561.913 | AE22: 1 | AF22: 1 | AG22: =AF22+AE22 -> 2 | AH22: 1 | AI22: =(AG22+AH22) -> 3 | AJ22: 0 | AK22: 1 | AL22: 1 | AM22: 1 | AN22: =AJ22+AK22+AL22+AM22 -> 3 | AO22: =P21-M21 -> 0 | AP22: =AO22+AD22-AI22-AN22 -> 12555.913
AE23: =SUM(AE20:AE22) -> 3 | AF23: =SUM(AF20:AF22) -> 3 | AG23: =SUM(AG20:AG22) -> 6
F24: Bamboo Pruning | G24: 1 | H24: Non-soil | I24: b | J24: 44 | K24: 12 | P24: =N24+O24 -> 0 | Q24: =2*5000 -> 10000 | R24: =Q24 -> 10000 | S24: 0.77 | T24: 0.89 | U24: =(Q24*S24*T24) -> 6853 | V24: 2 | W24: 2 | X24: =V24+W24 -> 4 | Y24: 0 | Z24: 2 | AA24: 2 | AB24: =Z24+AA24 -> 4 | AC24: =($X$27+$Y$27+$AB$27)*(Q24/$R$27) -> 3.84 | AD24: =(U24*J24/K24)-AC24 -> 25123.827 | AE24: 1.5 | AF24: 1.5 | AG24: =AF24+AE24 -> 3 | AH24: 1.5 | AI24: =(AG24+AH24) -> 4.5 | AJ24: 0 | AK24: 1 | AL24: 1 | AM24: 1 | AN24: =AJ24+AK24+AL24+AM24 -> 3 | AO24: =P22-M22 -> 0 | AP24: =AO24+AD24-AI24-AN24 -> 25116.327
F25: Paddy Straw | G25: 1 | H25: Non-soil | I25: b | J25: 44 | K25: 12 | P25: =N25+O25 -> 0 | Q25: =9.5*5000 -> 47500 | R25: =Q25 -> 47500 | S25: 0.49 | T25: 0.89 | U25: =(Q25*S25*T25) -> 20714.75 | V25: 2 | W25: 2 | X25: =V25+W25 -> 4 | Y25: 0 | Z25: 2 | AA25: 2 | AB25: =Z25+AA25 -> 4 | AC25: =($X$27+$Y$27+$AB$27)*(Q25/$R$27) -> 18.24 | AD25: =(U25*J25/K25)-AC25 -> 75935.843 | AE25: 1.5 | AF25: 1.5 | AG25: =AF25+AE25 -> 3 | AH25: 1.5 | AI25: =(AG25+AH25) -> 4.5 | AJ25: 0 | AK25: 1 | AL25: 1 | AM25: 1 | AN25: =AJ25+AK25+AL25+AM25 -> 3 | AO25: =P24-M24 -> 0 | AP25: =AO25+AD25-AI25-AN25 -> 75928.343
F26: Tree Pruning | G26: 1 | H26: Non-soil | I26: b | J26: 44 | K26: 12 | P26: =N26+O26 -> 0 | Q26: =1*5000 -> 5000 | R26: =Q26 -> 5000 | S26: 0.77 | T26: 0.89 | U26: =(Q26*S26*T26) -> 3426.5 | V26: 2 | W26: 2 | X26: =V26+W26 -> 4 | Y26: 0 | Z26: 2 | AA26: 2 | AB26: =Z26+AA26 -> 4 | AC26: =($X$27+$Y$27+$AB$27)*(Q26/$R$27) -> 1.92 | AD26: =(U26*J26/K26)-AC26 -> 12561.913 | AE26: 1.5 | AF26: 1.5 | AG26: =AF26+AE26 -> 3 | AH26: 1.5 | AI26: =(AG26+AH26) -> 4.5 | AJ26: 0 | AK26: 1 | AL26: 1 | AM26: 1 | AN26: =AJ26+AK26+AL26+AM26 -> 3 | AO26: =P25-M25 -> 0 | AP26: =AO26+AD26-AI26-AN26 -> 12554.413
R27: =SUM(R20:R26) -> 125000 | V27: =SUM(V20:V26) -> 12 | W27: =SUM(W20:W26) -> 12 | X27: =SUM(X20:X26) -> 24 | Y27: =SUM(Y20:Y26) -> 0 | Z27: =SUM(Z20:Z26) -> 12 | AA27: =SUM(AA20:AA26) -> 12 | AB27: =SUM(AB20:AB26) -> 24 | AC27: =SUM(AC20:AC26) -> 48 | AD27: =SUM(AD20:AD26) -> 227243.17 | AE27: =SUM(AE24:AE26) -> 4.5 | AF27: =SUM(AF24:AF26) -> 4.5 | AG27: =SUM(AG24:AG26) -> 9 | AJ27: =SUM(AJ24:AJ26) -> 0 | AK27: =SUM(AK24:AK26) -> 3 | AL27: =SUM(AL24:AL26) -> 3 | AM27: =SUM(AM24:AM26) -> 3 | AN27: =SUM(AN20:AN26) -> 18 | AO27: =SUM(AO20:AO26) -> 0
F28: Bamboo Pruning | G28: 2 | H28: Soil | I28: a | J28: 44 | K28: 12 | P28: =N28+O28 -> 0 | Q28: =2*5000 -> 10000 | R28: =Q28 -> 10000 | S28: 0.77 | T28: 0.89 | U28: =(Q28*S28*T28) -> 6853 | V28: 1.5 | W28: 1.5 | X28: =V28+W28 -> 3 | Y28: 0 | Z28: 1.5 | AA28: 1.5 | AB28: =Z28+AA28 -> 3 | AC28: =($X$35+$Y$35+$AB$35)*(Q28/$R$35) -> 2.88 | AD28: =(U28*J28/K28)-AC28 -> 25124.787 | AE28: 1 | AF28: 1 | AG28: =AF28+AE28 -> 2 | AH28: 1 | AI28: =(AG28+AH28) -> 3 | AJ28: 0 | AK28: 1 | AL28: 1 | AM28: 1 | AN28: =AJ28+AK28+AL28+AM28 -> 3 | AO28: =P12-M12 -> 0 | AP28: =AO28+AD28-AI28-AN28 -> 25118.787
F29: Paddy Straw | G29: 2 | H29: Soil | I29: a | J29: 44 | K29: 12 | P29: =N29+O29 -> 0 | Q29: =9.5*5000 -> 47500 | R29: =Q29 -> 47500 | S29: 0.49 | T29: 0.89 | U29: =(Q29*S29*T29) -> 20714.75 | V29: 1.5 | W29: 1.5 | X29: =V29+W29 -> 3 | Y29: 0 | Z29: 1.5 | AA29: 1.5 | AB29: =Z29+AA29 -> 3 | AC29: =($X$35+$Y$35+$AB$35)*(Q29/$R$35) -> 13.68 | AD29: =(U29*J29/K29)-AC29 -> 75940.403 | AE29: 1 | AF29: 1 | AG29: =AF29+AE29 -> 2 | AH29: 1 | AI29: =(AG29+AH29) -> 3 | AJ29: 0 | AK29: 1 | AL29: 1 | AM29: 1 | AN29: =AJ29+AK29+AL29+AM29 -> 3 | AO29: =P28-M28 -> 0 | AP29: =AO29+AD29-AI29-AN29 -> 75934.403
F30: Tree Pruning | G30: 2 | H30: Soil | I30: a | J30: 44 | K30: 12 | P30: =N30+O30 -> 0 | Q30: =1*5000 -> 5000 | R30: =Q30 -> 5000 | S30: 0.77 | T30: 0.89 | U30: =(Q30*S30*T30) -> 3426.5 | V30: 1.5 | W30: 1.5 | X30: =V30+W30 -> 3 | Y30: 0 | Z30: 1.5 | AA30: 1.5 | AB30: =Z30+AA30 -> 3 | AC30: =($X$35+$Y$35+$AB$35)*(Q30/$R$35) -> 1.44 | AD30: =(U30*J30/K30)-AC30 -> 12562.393 | AE30: 1 | AF30: 1 | AG30: =AF30+AE30 -> 2 | AH30: 1 | AI30: =(AG30+AH30) -> 3 | AJ30: 0 | AK30: 1 | AL30: 1 | AM30: 1 | AN30: =AJ30+AK30+AL30+AM30 -> 3 | AO30: =P29-M29 -> 0 | AP30: =AO30+AD30-AI30-AN30 -> 12556.393
AE31: =SUM(AE28:AE30) -> 3 | AF31: =SUM(AF28:AF30) -> 3 | AG31: =SUM(AG28:AG30) -> 6
F32: Bamboo Pruning | G32: 2 | H32: Non-soil | I32: a | J32: 44 | K32: 12 | P32: =N32+O32 -> 0 | Q32: =2*5000 -> 10000 | R32: =Q32 -> 10000 | S32: 0.77 | T32: 0.89 | U32: =(Q32*S32*T32) -> 6853 | V32: 1.5 | W32: 1.5 | X32: =V32+W32 -> 3 | Y32: 0 | Z32: 1.5 | AA32: 1.5 | AB32: =Z32+AA32 -> 3 | AC32: =($X$35+$Y$35+$AB$35)*(Q32/$R$35) -> 2.88 | AD32: =(U32*J32/K32)-AC32 -> 25124.787 | AE32: 1.5 | AF32: 1.5 | AG32: =AF32+AE32 -> 3 | AH32: 1.5 | AI32: =(AG32+AH32) -> 4.5 | AJ32: 0 | AK32: 2 | AL32: 2 | AM32: 2 | AN32: =AJ32+AK32+AL32+AM32 -> 6 | AO32: =P16-M16 -> 0 | AP32: =AO32+AD32-AI32-AN32 -> 25114.287
F33: Paddy Straw | G33: 2 | H33: Non-soil | I33: a | J33: 44 | K33: 12 | P33: =N33+O33 -> 0 | Q33: =9.5*5000 -> 47500 | R33: =Q33 -> 47500 | S33: 0.49 | T33: 0.89 | U33: =(Q33*S33*T33) -> 20714.75 | V33: 1.5 | W33: 1.5 | X33: =V33+W33 -> 3 | Y33: 0 | Z33: 1.5 | AA33: 1.5 | AB33: =Z33+AA33 -> 3 | AC33: =($X$35+$Y$35+$AB$35)*(Q33/$R$35) -> 13.68 | AD33: =(U33*J33/K33)-AC33 -> 75940.403 | AE33: 1.5 | AF33: 1.5 | AG33: =AF33+AE33 -> 3 | AH33: 1.5 | AI33: =(AG33+AH33) -> 4.5 | AJ33: 0 | AK33: 2 | AL33: 2 | AM33: 2 | AN33: =AJ33+AK33+AL33+AM33 -> 6 | AO33: =P32-M32 -> 0 | AP33: =AO33+AD33-AI33-AN33 -> 75929.903
F34: Tree Pruning | G34: 2 | H34: Non-soil | I34: a | J34: 44 | K34: 12 | P34: =N34+O34 -> 0 | Q34: =1*5000 -> 5000 | R34: =Q34 -> 5000 | S34: 0.77 | T34: 0.89 | U34: =(Q34*S34*T34) -> 3426.5 | V34: 1.5 | W34: 1.5 | X34: =V34+W34 -> 3 | Y34: 0 | Z34: 1.5 | AA34: 1.5 | AB34: =Z34+AA34 -> 3 | AC34: =($X$35+$Y$35+$AB$35)*(Q34/$R$35) -> 1.44 | AD34: =(U34*J34/K34)-AC34 -> 12562.393 | AE34: 1.5 | AF34: 1.5 | AG34: =AF34+AE34 -> 3 | AH34: 1.5 | AI34: =(AG34+AH34) -> 4.5 | AJ34: 0 | AK34: 2 | AL34: 2 | AM34: 2 | AN34: =AJ34+AK34+AL34+AM34 -> 6 | AO34: =P33-M33 -> 0 | AP34: =AO34+AD34-AI34-AN34 -> 12551.893
R35: =SUM(R28:R34) -> 125000 | V35: =SUM(V28:V34) -> 9 | W35: =SUM(W28:W34) -> 9 | X35: =SUM(X28:X34) -> 18 | Y35: =SUM(Y28:Y34) -> 0 | Z35: =SUM(Z28:Z34) -> 9 | AA35: =SUM(AA28:AA34) -> 9 | AB35: =SUM(AB28:AB34) -> 18 | AC35: =SUM(AC28:AC34) -> 36 | AD35: =SUM(AD28:AD34) -> 227255.17 | AE35: =SUM(AE32:AE34) -> 4.5 | AF35: =SUM(AF32:AF34) -> 4.5 | AG35: =SUM(AG32:AG34) -> 9 | AJ35: =SUM(AJ32:AJ34) -> 0 | AK35: =SUM(AK32:AK34) -> 6 | AL35: =SUM(AL32:AL34) -> 6 | AM35: =SUM(AM32:AM34) -> 6 | AN35: =SUM(AN28:AN34) -> 27 | AO35: =SUM(AO28:AO34) -> 0
F36: Bamboo Pruning | G36: 2 | H36: Soil | I36: b | J36: 44 | K36: 12 | P36: =N36+O36 -> 0 | Q36: =2*5000 -> 10000 | R36: =Q36 -> 10000 | S36: 0.77 | T36: 0.89 | U36: =(Q36*S36*T36) -> 6853 | V36: 2.5 | W36: 2.5 | X36: =V36+W36 -> 5 | Y36: 0 | Z36: 2.5 | AA36: 2.5 | AB36: =Z36+AA36 -> 5 | AC36: =($X$43+$Y$43+$AB$43)*(Q36/$R$43) -> 4.8 | AD36: =(U36*J36/K36)-AC36 -> 25122.867 | AE36: 1 | AF36: 1 | AG36: =AF36+AE36 -> 2 | AH36: 1 | AI36: =(AG36+AH36) -> 3 | AJ36: 0 | AK36: 2 | AL36: 2 | AM36: 2 | AN36: =AJ36+AK36+AL36+AM36 -> 6 | AO36: =P20-M20 -> 0 | AP36: =AO36+AD36-AI36-AN36 -> 25113.867
F37: Paddy Straw | G37: 2 | H37: Soil | I37: b | J37: 44 | K37: 12 | P37: =N37+O37 -> 0 | Q37: =9.5*5000 -> 47500 | R37: =Q37 -> 47500 | S37: 0.49 | T37: 0.89 | U37: =(Q37*S37*T37) -> 20714.75 | V37: 2.5 | W37: 2.5 | X37: =V37+W37 -> 5 | Y37: 0 | Z37: 2.5 | AA37: 2.5 | AB37: =Z37+AA37 -> 5 | AC37: =($X$43+$Y$43+$AB$43)*(Q37/$R$43) -> 22.8 | AD37: =(U37*J37/K37)-AC37 -> 75931.283 | AE37: 1 | AF37: 1 | AG37: =AF37+AE37 -> 2 | AH37: 1 | AI37: =(AG37+AH37) -> 3 | AJ37: 0 | AK37: 2 | AL37: 2 | AM37: 2 | AN37: =AJ37+AK37+AL37+AM37 -> 6 | AO37: =P36-M36 -> 0 | AP37: =AO37+AD37-AI37-AN37 -> 75922.283
F38: Tree Pruning | G38: 2 | H38: Soil | I38: b | J38: 44 | K38: 12 | P38: =N38+O38 -> 0 | Q38: =1*5000 -> 5000 | R38: =Q38 -> 5000 | S38: 0.77 | T38: 0.89 | U38: =(Q38*S38*T38) -> 3426.5 | V38: 2.5 | W38: 2.5 | X38: =V38+W38 -> 5 | Y38: 0 | Z38: 2.5 | AA38: 2.5 | AB38: =Z38+AA38 -> 5 | AC38: =($X$43+$Y$43+$AB$43)*(Q38/$R$43) -> 2.4 | AD38: =(U38*J38/K38)-AC38 -> 12561.433 | AE38: 1 | AF38: 1 | AG38: =AF38+AE38 -> 2 | AH38: 1 | AI38: =(AG38+AH38) -> 3 | AJ38: 0 | AK38: 2 | AL38: 2 | AM38: 2 | AN38: =AJ38+AK38+AL38+AM38 -> 6 | AO38: =P37-M37 -> 0 | AP38: =AO38+AD38-AI38-AN38 -> 12552.433
AE39: =SUM(AE36:AE38) -> 3 | AF39: =SUM(AF36:AF38) -> 3 | AG39: =SUM(AG36:AG38) -> 6 | AJ39: =SUM(AJ36:AJ38) -> 0 | AK39: =SUM(AK36:AK38) -> 6 | AL39: =SUM(AL36:AL38) -> 6 | AM39: =SUM(AM36:AM38) -> 6
F40: Bamboo Pruning | G40: 2 | H40: Non-soil | I40: b | J40: 44 | K40: 12 | P40: =N40+O40 -> 0 | Q40: =2*5000 -> 10000 | R40: =Q40 -> 10000 | S40: 0.77 | T40: 0.89 | U40: =(Q40*S40*T40) -> 6853 | V40: 2.5 | W40: 2.5 | X40: =V40+W40 -> 5 | Y40: 0 | Z40: 2.5 | AA40: 2.5 | AB40: =Z40+AA40 -> 5 | AC40: =($X$43+$Y$43+$AB$43)*(Q40/$R$43) -> 4.8 | AD40: =(U40*J40/K40)-AC40 -> 25122.867 | AE40: 1.5 | AF40: 1.5 | AG40: =AF40+AE40 -> 3 | AH40: 1.5 | AI40: =(AG40+AH40) -> 4.5 | AJ40: 0 | AK40: 2 | AL40: 2 | AM40: 2 | AN40: =AJ40+AK40+AL40+AM40 -> 6 | AO40: =P24-M24 -> 0 | AP40: =AO40+AD40-AI40-AN40 -> 25112.367
F41: Paddy Straw | G41: 2 | H41: Non-soil | I41: b | J41: 44 | K41: 12 | P41: =N41+O41 -> 0 | Q41: =9.5*5000 -> 47500 | R41: =Q41 -> 47500 | S41: 0.49 | T41: 0.89 | U41: =(Q41*S41*T41) -> 20714.75 | V41: 2.5 | W41: 2.5 | X41: =V41+W41 -> 5 | Y41: 0 | Z41: 2.5 | AA41: 2.5 | AB41: =Z41+AA41 -> 5 | AC41: =($X$43+$Y$43+$AB$43)*(Q41/$R$43) -> 22.8 | AD41: =(U41*J41/K41)-AC41 -> 75931.283 | AE41: 1.5 | AF41: 1.5 | AG41: =AF41+AE41 -> 3 | AH41: 1.5 | AI41: =(AG41+AH41) -> 4.5 | AJ41: 0 | AK41: 2 | AL41: 2 | AM41: 2 | AN41: =AJ41+AK41+AL41+AM41 -> 6 | AO41: =P40-M40 -> 0 | AP41: =AO41+AD41-AI41-AN41 -> 75920.783
F42: Tree Pruning | G42: 2 | H42: Non-soil | I42: b | J42: 44 | K42: 12 | P42: =N42+O42 -> 0 | Q42: =1*5000 -> 5000 | R42: =Q42 -> 5000 | S42: 0.77 | T42: 0.89 | U42: =(Q42*S42*T42) -> 3426.5 | V42: 2.5 | W42: 2.5 | X42: =V42+W42 -> 5 | Y42: 0 | Z42: 2.5 | AA42: 2.5 | AB42: =Z42+AA42 -> 5 | AC42: =($X$43+$Y$43+$AB$43)*(Q42/$R$43) -> 2.4 | AD42: =(U42*J42/K42)-AC42 -> 12561.433 | AE42: 1.5 | AF42: 1.5 | AG42: =AF42+AE42 -> 3 | AH42: 1.5 | AI42: =(AG42+AH42) -> 4.5 | AJ42: 0 | AK42: 2 | AL42: 2 | AM42: 2 | AN42: =AJ42+AK42+AL42+AM42 -> 6 | AO42: =P41-M41 -> 0 | AP42: =AO42+AD42-AI42-AN42 -> 12550.933
R43: =SUM(R36:R42) -> 125000 | V43: =SUM(V36:V42) -> 15 | W43: =SUM(W36:W42) -> 15 | X43: =SUM(X36:X42) -> 30 | Y43: =SUM(Y36:Y42) -> 0 | Z43: =SUM(Z36:Z42) -> 15 | AA43: =SUM(AA36:AA42) -> 15 | AB43: =SUM(AB36:AB42) -> 30 | AC43: =SUM(AC36:AC42) -> 60 | AD43: =SUM(AD36:AD42) -> 227231.17 | AE43: =SUM(AE40:AE42) -> 4.5 | AF43: =SUM(AF40:AF42) -> 4.5 | AG43: =SUM(AG40:AG42) -> 9 | AJ43: =SUM(AJ40:AJ42) -> 0 | AK43: =SUM(AK40:AK42) -> 6 | AL43: =SUM(AL40:AL42) -> 6 | AM43: =SUM(AM40:AM42) -> 6 | AN43: =SUM(AN36:AN42) -> 36 | AO43: =SUM(AO36:AO42) -> 0
F44: https://projecthub-uat.verra.org/project-description/1601 | AP44: =SUM(AP12:AP42) -> 908807.67
...

Sheet Lists
A1: Option to calculate Fuel emissions | B1: Applicability
A2: Option A1 | B2: Applicable
A3: Option A2 | B3: Not Applicable
A4: Option B

Sheet Test Data High Tech(April 2025)
A2: Baseline emissions
H5: Table 1: Baseline Emissions at sourcing stage
I6: VM0044
I7: section 8.1.1.
H8: Year | I8: BESS,y
I9: tCO2e
H10: 2020 | I10: =SUMIFS('Data input'!$J$9:$J$15,'Data input'!$I$9:$I$15,H10) -> 0
H11: 2021 | I11: =SUMIFS('Data input'!$J$9:$J$15,'Data input'!$I$9:$I$15,H11) -> 0
H12: 2022 | I12: =SUMIFS('Data input'!$J$9:$J$15,'Data input'!$I$9:$I$15,H12) -> 0
H13: 2023 | I13: =SUMIFS('Data input'!$J$9:$J$15,'Data input'!$I$9:$I$15,H13) -> 0
H14: 2024 | I14: =SUMIFS('Data input'!$J$9:$J$15,'Data input'!$I$9:$I$15,H14) -> 0
H15: 2025 | I15: =SUMIFS('Data input'!$J$9:$J$15,'Data input'!$I$9:$I$15,H15) -> 0
H16: 2026 | I16: =SUMIFS('Data input'!$J$9:$J$15,'Data input'!$I$9:$I$15,H16) -> 0
A18: Project emissions
H20: Table 2: Project emissions at production stage
K21: VM0044
K22: Equation 1
H23: Year | I23: CCt,k,y | J23: PEPS,t,p,y | K23: ERPS,y
I24: tonnes | J24: tCO2e | K24: tCO2e
H25: 2020 | I25: =SUMIFS($O$39:$O$94,$H$39:$H$94,H25) -> 747.9122 | J25: =SUMIFS($N$110:$N$116,$H$110:$H$116,H25) -> 296.22991 | K25: =(I25)*(44/12)-J25 -> 2446.1148
H26: 2021 | I26: =SUMIFS($O$39:$O$94,$H$39:$H$94,H26) -> 767.541 | J26: =SUMIFS($N$110:$N$116,$H$110:$H$116,H26) -> 318.10311 | K26: =(I26)*(44/12)-J26 -> 2496.2139
H27: 2022 | I27: =SUMIFS($O$39:$O$94,$H$39:$H$94,H27) -> 787.3146 | J27: =SUMIFS($N$110:$N$116,$H$110:$H$116,H27) -> 353.94327 | K27: =(I27)*(44/12)-J27 -> 2532.8769
H28: 2023 | I28: =SUMIFS($O$39:$O$94,$H$39:$H$94,H28) -> 807.233 | J28: =SUMIFS($N$110:$N$116,$H$110:$H$116,H28) -> 318.8655 | K28: =(I28)*(44/12)-J28 -> 2640.9888
H29: 2024 | I29: =SUMIFS($O$39:$O$94,$H$39:$H$94,H29) -> 827.2962 | J29: =SUMIFS($N$110:$N$116,$H$110:$H$116,H29) -> 257.67675 | K29: =(I29)*(44/12)-J29 -> 2775.7427
H30: 2025 | I30: =SUMIFS($O$39:$O$94,$H$39:$H$94,H30) -> 847.5042 | J30: =SUMIFS($N$110:$N$116,$H$110:$H$116,H30) -> 316.41715 | K30: =(I30)*(44/12)-J30 -> 2791.0982
H31: 2026 | I31: =SUMIFS($O$39:$O$94,$H$39:$H$94,H31) -> 867.857 | J31: =SUMIFS($N$110:$N$116,$H$110:$H$116,H31) -> 448.12778 | K31: =(I31)*(44/12)-J31 -> 2734.0146
H34: Table 3: Estimation of total organic carbon content on a dry weight basis attributable to the project activity for High Tech facilities
O35: VM0044
O36: Equation 2 | P36: Use equation 6 for low tech production
H37: Year | I37: Biochar Type (t) | J37: Application Type (k) | K37: Production Facility (p) | L37: Mt,k,p,y | M37: FCp,t,p | N37: PRde,k | O37: CCt,k,y
L38: tonnes | M38: Percent | O38: tonnes
H39: 2020 | I39: Bamboo Pruning | J39: Soil | K39: PF1 | L39: =SUMIFS('Data input'!$M$23:$M$78,'Data input'!$I$23:$I$78,H39,'Data input'!$J$23:$J$78,I39,'Data input'!$K$23:$K$78,J39,'Data input'!$L$23:$L$78,K39) -> 200 | M39: {=_xlfn.XLOOKUP(H39&I39&K39,'Data input'!$I$83:$I$110&'Data input'!$J$83:$J$110&'Data input'!$K$83:$K$110,'Data input'!$L$83:$L$110)} -> 0.35 | N39: =_xlfn.XLOOKUP(J39,'Data input'!$I$115:$I$116,'Data input'!$J$115:$J$116) -> 0.89 | O39: =L39*M39*N39 -> 62.3
